>> anaconda-3-5.3.1 has been loaded.
>> python-3.8.2 has been loaded.
>> cuda-10.1_cudnn-7.6.5 has been loaded.
WARNING: Value for scheme.headers does not match. Please report this to <https://github.com/pypa/pip/issues/10151>
distutils: /home/arlan.uy/.local/include/python3.7m/UNKNOWN
sysconfig: /home/arlan.uy/.local/include/python3.7/UNKNOWN
WARNING: Additional context:
user = True
home = None
root = None
prefix = None
WARNING: Value for scheme.headers does not match. Please report this to <https://github.com/pypa/pip/issues/10151>
distutils: /home/arlan.uy/.local/include/python3.7m/UNKNOWN
sysconfig: /home/arlan.uy/.local/include/python3.7/UNKNOWN
WARNING: Value for scheme.headers does not match. Please report this to <https://github.com/pypa/pip/issues/10151>
distutils: /home/arlan.uy/.local/include/python3.7m/UNKNOWN
sysconfig: /home/arlan.uy/.local/include/python3.7/UNKNOWN
WARNING: Additional context:
user = True
home = None
root = None
prefix = None
WARNING: Additional context:
user = True
home = None
root = None
prefix = None
WARNING: Value for scheme.headers does not match. Please report this to <https://github.com/pypa/pip/issues/10151>
distutils: /home/arlan.uy/.local/include/python3.7m/UNKNOWN
sysconfig: /home/arlan.uy/.local/include/python3.7/UNKNOWN
WARNING: Additional context:
user = True
home = None
root = None
prefix = None
WARNING: Value for scheme.headers does not match. Please report this to <https://github.com/pypa/pip/issues/10151>
distutils: /home/arlan.uy/.local/include/python3.7m/UNKNOWN
sysconfig: /home/arlan.uy/.local/include/python3.7/UNKNOWN
WARNING: Additional context:
user = True
home = None
root = None
prefix = None
WARNING: Value for scheme.headers does not match. Please report this to <https://github.com/pypa/pip/issues/10151>
distutils: /home/arlan.uy/.local/include/python3.7m/UNKNOWN
sysconfig: /home/arlan.uy/.local/include/python3.7/UNKNOWN
WARNING: Additional context:
user = True
home = None
root = None
prefix = None
WARNING: Value for scheme.headers does not match. Please report this to <https://github.com/pypa/pip/issues/10151>
distutils: /home/arlan.uy/.local/include/python3.7m/UNKNOWN
sysconfig: /home/arlan.uy/.local/include/python3.7/UNKNOWN
WARNING: Additional context:
user = True
home = None
root = None
prefix = None
WARNING: Value for scheme.headers does not match. Please report this to <https://github.com/pypa/pip/issues/10151>
distutils: /home/arlan.uy/.local/include/python3.7m/UNKNOWN
sysconfig: /home/arlan.uy/.local/include/python3.7/UNKNOWN
WARNING: Additional context:
user = True
home = None
root = None
prefix = None
Traceback (most recent call last):
  File "/opt/hpcc/CPU/anaconda/3-5.3.1/lib/python3.7/runpy.py", line 193, in _run_module_as_main
    "__main__", mod_spec)
  File "/opt/hpcc/CPU/anaconda/3-5.3.1/lib/python3.7/runpy.py", line 85, in _run_code
    exec(code, run_globals)
  File "/home/arlan.uy/.local/lib/python3.7/site-packages/pip/__main__.py", line 29, in <module>
    from pip._internal.cli.main import main as _main
  File "/home/arlan.uy/.local/lib/python3.7/site-packages/pip/_internal/cli/main.py", line 9, in <module>
    from pip._internal.cli.autocompletion import autocomplete
  File "/home/arlan.uy/.local/lib/python3.7/site-packages/pip/_internal/cli/autocompletion.py", line 10, in <module>
    from pip._internal.cli.main_parser import create_main_parser
  File "/home/arlan.uy/.local/lib/python3.7/site-packages/pip/_internal/cli/main_parser.py", line 8, in <module>
    from pip._internal.cli import cmdoptions
  File "/home/arlan.uy/.local/lib/python3.7/site-packages/pip/_internal/cli/cmdoptions.py", line 23, in <module>
    from pip._internal.cli.parser import ConfigOptionParser
  File "/home/arlan.uy/.local/lib/python3.7/site-packages/pip/_internal/cli/parser.py", line 12, in <module>
    from pip._internal.configuration import Configuration, ConfigurationError
  File "/home/arlan.uy/.local/lib/python3.7/site-packages/pip/_internal/configuration.py", line 21, in <module>
    from pip._internal.exceptions import (
  File "/home/arlan.uy/.local/lib/python3.7/site-packages/pip/_internal/exceptions.py", line 7, in <module>
    from pip._vendor.pkg_resources import Distribution
  File "/home/arlan.uy/.local/lib/python3.7/site-packages/pip/_vendor/pkg_resources/__init__.py", line 3251, in <module>
    @_call_aside
  File "/home/arlan.uy/.local/lib/python3.7/site-packages/pip/_vendor/pkg_resources/__init__.py", line 3235, in _call_aside
    f(*args, **kwargs)
  File "/home/arlan.uy/.local/lib/python3.7/site-packages/pip/_vendor/pkg_resources/__init__.py", line 3287, in _initialize_master_working_set
    list(map(working_set.add_entry, sys.path))
  File "/home/arlan.uy/.local/lib/python3.7/site-packages/pip/_vendor/pkg_resources/__init__.py", line 623, in add_entry
    for dist in find_distributions(entry, True):
  File "/home/arlan.uy/.local/lib/python3.7/site-packages/pip/_vendor/pkg_resources/__init__.py", line 2065, in find_on_path
    for dist in factory(fullpath):
  File "/home/arlan.uy/.local/lib/python3.7/site-packages/pip/_vendor/pkg_resources/__init__.py", line 2135, in distributions_from_metadata
    root, entry, metadata, precedence=DEVELOP_DIST,
  File "/home/arlan.uy/.local/lib/python3.7/site-packages/pip/_vendor/pkg_resources/__init__.py", line 2592, in from_location
    py_version=py_version, platform=platform, **kw
  File "/home/arlan.uy/.local/lib/python3.7/site-packages/pip/_vendor/pkg_resources/__init__.py", line 2994, in _reload_version
    md_version = self._get_version()
  File "/home/arlan.uy/.local/lib/python3.7/site-packages/pip/_vendor/pkg_resources/__init__.py", line 2772, in _get_version
    version = _version_from_file(lines)
  File "/home/arlan.uy/.local/lib/python3.7/site-packages/pip/_vendor/pkg_resources/__init__.py", line 2556, in _version_from_file
    line = next(iter(version_lines), '')
  File "/home/arlan.uy/.local/lib/python3.7/site-packages/pip/_vendor/pkg_resources/__init__.py", line 2767, in _get_metadata
    for line in self.get_metadata_lines(name):
  File "/home/arlan.uy/.local/lib/python3.7/site-packages/pip/_vendor/pkg_resources/__init__.py", line 1911, in get_metadata_lines
    return yield_lines(self.get_metadata(name))
  File "/home/arlan.uy/.local/lib/python3.7/site-packages/pip/_vendor/pkg_resources/__init__.py", line 1897, in get_metadata
    with io.open(self.path, encoding='utf-8', errors="replace") as f:
OSError: [Errno 5] Input/output error: '/share/hpcc/CPU/anaconda/3-5.3.1/lib/python3.7/site-packages/docutils-0.14-py3.7.egg-info'
Traceback (most recent call last):
  File "/opt/hpcc/CPU/anaconda/3-5.3.1/lib/python3.7/runpy.py", line 193, in _run_module_as_main
    "__main__", mod_spec)
  File "/opt/hpcc/CPU/anaconda/3-5.3.1/lib/python3.7/runpy.py", line 85, in _run_code
    exec(code, run_globals)
  File "/home/arlan.uy/.local/lib/python3.7/site-packages/pip/__main__.py", line 29, in <module>
    from pip._internal.cli.main import main as _main
  File "/home/arlan.uy/.local/lib/python3.7/site-packages/pip/_internal/cli/main.py", line 9, in <module>
    from pip._internal.cli.autocompletion import autocomplete
  File "/home/arlan.uy/.local/lib/python3.7/site-packages/pip/_internal/cli/autocompletion.py", line 10, in <module>
    from pip._internal.cli.main_parser import create_main_parser
  File "/home/arlan.uy/.local/lib/python3.7/site-packages/pip/_internal/cli/main_parser.py", line 8, in <module>
    from pip._internal.cli import cmdoptions
  File "/home/arlan.uy/.local/lib/python3.7/site-packages/pip/_internal/cli/cmdoptions.py", line 23, in <module>
    from pip._internal.cli.parser import ConfigOptionParser
  File "/home/arlan.uy/.local/lib/python3.7/site-packages/pip/_internal/cli/parser.py", line 12, in <module>
    from pip._internal.configuration import Configuration, ConfigurationError
  File "/home/arlan.uy/.local/lib/python3.7/site-packages/pip/_internal/configuration.py", line 21, in <module>
    from pip._internal.exceptions import (
  File "/home/arlan.uy/.local/lib/python3.7/site-packages/pip/_internal/exceptions.py", line 7, in <module>
    from pip._vendor.pkg_resources import Distribution
  File "/home/arlan.uy/.local/lib/python3.7/site-packages/pip/_vendor/pkg_resources/__init__.py", line 3251, in <module>
    @_call_aside
  File "/home/arlan.uy/.local/lib/python3.7/site-packages/pip/_vendor/pkg_resources/__init__.py", line 3235, in _call_aside
    f(*args, **kwargs)
  File "/home/arlan.uy/.local/lib/python3.7/site-packages/pip/_vendor/pkg_resources/__init__.py", line 3287, in _initialize_master_working_set
    list(map(working_set.add_entry, sys.path))
  File "/home/arlan.uy/.local/lib/python3.7/site-packages/pip/_vendor/pkg_resources/__init__.py", line 623, in add_entry
    for dist in find_distributions(entry, True):
  File "/home/arlan.uy/.local/lib/python3.7/site-packages/pip/_vendor/pkg_resources/__init__.py", line 2065, in find_on_path
    for dist in factory(fullpath):
  File "/home/arlan.uy/.local/lib/python3.7/site-packages/pip/_vendor/pkg_resources/__init__.py", line 2135, in distributions_from_metadata
    root, entry, metadata, precedence=DEVELOP_DIST,
  File "/home/arlan.uy/.local/lib/python3.7/site-packages/pip/_vendor/pkg_resources/__init__.py", line 2592, in from_location
    py_version=py_version, platform=platform, **kw
  File "/home/arlan.uy/.local/lib/python3.7/site-packages/pip/_vendor/pkg_resources/__init__.py", line 2994, in _reload_version
    md_version = self._get_version()
  File "/home/arlan.uy/.local/lib/python3.7/site-packages/pip/_vendor/pkg_resources/__init__.py", line 2772, in _get_version
    version = _version_from_file(lines)
  File "/home/arlan.uy/.local/lib/python3.7/site-packages/pip/_vendor/pkg_resources/__init__.py", line 2556, in _version_from_file
    line = next(iter(version_lines), '')
  File "/home/arlan.uy/.local/lib/python3.7/site-packages/pip/_vendor/pkg_resources/__init__.py", line 2767, in _get_metadata
    for line in self.get_metadata_lines(name):
  File "/home/arlan.uy/.local/lib/python3.7/site-packages/pip/_vendor/pkg_resources/__init__.py", line 1911, in get_metadata_lines
    return yield_lines(self.get_metadata(name))
  File "/home/arlan.uy/.local/lib/python3.7/site-packages/pip/_vendor/pkg_resources/__init__.py", line 1897, in get_metadata
    with io.open(self.path, encoding='utf-8', errors="replace") as f:
OSError: [Errno 5] Input/output error: '/share/hpcc/CPU/anaconda/3-5.3.1/lib/python3.7/site-packages/docutils-0.14-py3.7.egg-info'
Traceback (most recent call last):
  File "/opt/hpcc/CPU/anaconda/3-5.3.1/lib/python3.7/runpy.py", line 193, in _run_module_as_main
    "__main__", mod_spec)
  File "/opt/hpcc/CPU/anaconda/3-5.3.1/lib/python3.7/runpy.py", line 85, in _run_code
    exec(code, run_globals)
  File "/home/arlan.uy/.local/lib/python3.7/site-packages/pip/__main__.py", line 29, in <module>
    from pip._internal.cli.main import main as _main
  File "/home/arlan.uy/.local/lib/python3.7/site-packages/pip/_internal/cli/main.py", line 9, in <module>
    from pip._internal.cli.autocompletion import autocomplete
  File "/home/arlan.uy/.local/lib/python3.7/site-packages/pip/_internal/cli/autocompletion.py", line 10, in <module>
    from pip._internal.cli.main_parser import create_main_parser
  File "/home/arlan.uy/.local/lib/python3.7/site-packages/pip/_internal/cli/main_parser.py", line 8, in <module>
    from pip._internal.cli import cmdoptions
  File "/home/arlan.uy/.local/lib/python3.7/site-packages/pip/_internal/cli/cmdoptions.py", line 23, in <module>
    from pip._internal.cli.parser import ConfigOptionParser
  File "/home/arlan.uy/.local/lib/python3.7/site-packages/pip/_internal/cli/parser.py", line 12, in <module>
    from pip._internal.configuration import Configuration, ConfigurationError
  File "/home/arlan.uy/.local/lib/python3.7/site-packages/pip/_internal/configuration.py", line 21, in <module>
    from pip._internal.exceptions import (
  File "/home/arlan.uy/.local/lib/python3.7/site-packages/pip/_internal/exceptions.py", line 7, in <module>
    from pip._vendor.pkg_resources import Distribution
  File "/home/arlan.uy/.local/lib/python3.7/site-packages/pip/_vendor/pkg_resources/__init__.py", line 3251, in <module>
    @_call_aside
  File "/home/arlan.uy/.local/lib/python3.7/site-packages/pip/_vendor/pkg_resources/__init__.py", line 3235, in _call_aside
    f(*args, **kwargs)
  File "/home/arlan.uy/.local/lib/python3.7/site-packages/pip/_vendor/pkg_resources/__init__.py", line 3287, in _initialize_master_working_set
    list(map(working_set.add_entry, sys.path))
  File "/home/arlan.uy/.local/lib/python3.7/site-packages/pip/_vendor/pkg_resources/__init__.py", line 623, in add_entry
    for dist in find_distributions(entry, True):
  File "/home/arlan.uy/.local/lib/python3.7/site-packages/pip/_vendor/pkg_resources/__init__.py", line 2065, in find_on_path
    for dist in factory(fullpath):
  File "/home/arlan.uy/.local/lib/python3.7/site-packages/pip/_vendor/pkg_resources/__init__.py", line 2135, in distributions_from_metadata
    root, entry, metadata, precedence=DEVELOP_DIST,
  File "/home/arlan.uy/.local/lib/python3.7/site-packages/pip/_vendor/pkg_resources/__init__.py", line 2592, in from_location
    py_version=py_version, platform=platform, **kw
  File "/home/arlan.uy/.local/lib/python3.7/site-packages/pip/_vendor/pkg_resources/__init__.py", line 2994, in _reload_version
    md_version = self._get_version()
  File "/home/arlan.uy/.local/lib/python3.7/site-packages/pip/_vendor/pkg_resources/__init__.py", line 2772, in _get_version
    version = _version_from_file(lines)
  File "/home/arlan.uy/.local/lib/python3.7/site-packages/pip/_vendor/pkg_resources/__init__.py", line 2556, in _version_from_file
    line = next(iter(version_lines), '')
  File "/home/arlan.uy/.local/lib/python3.7/site-packages/pip/_vendor/pkg_resources/__init__.py", line 2767, in _get_metadata
    for line in self.get_metadata_lines(name):
  File "/home/arlan.uy/.local/lib/python3.7/site-packages/pip/_vendor/pkg_resources/__init__.py", line 1911, in get_metadata_lines
    return yield_lines(self.get_metadata(name))
  File "/home/arlan.uy/.local/lib/python3.7/site-packages/pip/_vendor/pkg_resources/__init__.py", line 1897, in get_metadata
    with io.open(self.path, encoding='utf-8', errors="replace") as f:
OSError: [Errno 5] Input/output error: '/share/hpcc/CPU/anaconda/3-5.3.1/lib/python3.7/site-packages/docutils-0.14-py3.7.egg-info'
Traceback (most recent call last):
  File "/opt/hpcc/CPU/anaconda/3-5.3.1/lib/python3.7/runpy.py", line 193, in _run_module_as_main
    "__main__", mod_spec)
  File "/opt/hpcc/CPU/anaconda/3-5.3.1/lib/python3.7/runpy.py", line 85, in _run_code
    exec(code, run_globals)
  File "/home/arlan.uy/.local/lib/python3.7/site-packages/pip/__main__.py", line 29, in <module>
    from pip._internal.cli.main import main as _main
  File "/home/arlan.uy/.local/lib/python3.7/site-packages/pip/_internal/cli/main.py", line 9, in <module>
    from pip._internal.cli.autocompletion import autocomplete
  File "/home/arlan.uy/.local/lib/python3.7/site-packages/pip/_internal/cli/autocompletion.py", line 10, in <module>
    from pip._internal.cli.main_parser import create_main_parser
  File "/home/arlan.uy/.local/lib/python3.7/site-packages/pip/_internal/cli/main_parser.py", line 8, in <module>
    from pip._internal.cli import cmdoptions
  File "/home/arlan.uy/.local/lib/python3.7/site-packages/pip/_internal/cli/cmdoptions.py", line 23, in <module>
    from pip._internal.cli.parser import ConfigOptionParser
  File "/home/arlan.uy/.local/lib/python3.7/site-packages/pip/_internal/cli/parser.py", line 12, in <module>
    from pip._internal.configuration import Configuration, ConfigurationError
  File "/home/arlan.uy/.local/lib/python3.7/site-packages/pip/_internal/configuration.py", line 21, in <module>
    from pip._internal.exceptions import (
  File "/home/arlan.uy/.local/lib/python3.7/site-packages/pip/_internal/exceptions.py", line 7, in <module>
    from pip._vendor.pkg_resources import Distribution
  File "/home/arlan.uy/.local/lib/python3.7/site-packages/pip/_vendor/pkg_resources/__init__.py", line 3251, in <module>
    @_call_aside
  File "/home/arlan.uy/.local/lib/python3.7/site-packages/pip/_vendor/pkg_resources/__init__.py", line 3235, in _call_aside
    f(*args, **kwargs)
  File "/home/arlan.uy/.local/lib/python3.7/site-packages/pip/_vendor/pkg_resources/__init__.py", line 3287, in _initialize_master_working_set
    list(map(working_set.add_entry, sys.path))
  File "/home/arlan.uy/.local/lib/python3.7/site-packages/pip/_vendor/pkg_resources/__init__.py", line 623, in add_entry
    for dist in find_distributions(entry, True):
  File "/home/arlan.uy/.local/lib/python3.7/site-packages/pip/_vendor/pkg_resources/__init__.py", line 2065, in find_on_path
    for dist in factory(fullpath):
  File "/home/arlan.uy/.local/lib/python3.7/site-packages/pip/_vendor/pkg_resources/__init__.py", line 2135, in distributions_from_metadata
    root, entry, metadata, precedence=DEVELOP_DIST,
  File "/home/arlan.uy/.local/lib/python3.7/site-packages/pip/_vendor/pkg_resources/__init__.py", line 2592, in from_location
    py_version=py_version, platform=platform, **kw
  File "/home/arlan.uy/.local/lib/python3.7/site-packages/pip/_vendor/pkg_resources/__init__.py", line 2994, in _reload_version
    md_version = self._get_version()
  File "/home/arlan.uy/.local/lib/python3.7/site-packages/pip/_vendor/pkg_resources/__init__.py", line 2772, in _get_version
    version = _version_from_file(lines)
  File "/home/arlan.uy/.local/lib/python3.7/site-packages/pip/_vendor/pkg_resources/__init__.py", line 2556, in _version_from_file
    line = next(iter(version_lines), '')
  File "/home/arlan.uy/.local/lib/python3.7/site-packages/pip/_vendor/pkg_resources/__init__.py", line 2767, in _get_metadata
    for line in self.get_metadata_lines(name):
  File "/home/arlan.uy/.local/lib/python3.7/site-packages/pip/_vendor/pkg_resources/__init__.py", line 1911, in get_metadata_lines
    return yield_lines(self.get_metadata(name))
  File "/home/arlan.uy/.local/lib/python3.7/site-packages/pip/_vendor/pkg_resources/__init__.py", line 1897, in get_metadata
    with io.open(self.path, encoding='utf-8', errors="replace") as f:
OSError: [Errno 5] Input/output error: '/share/hpcc/CPU/anaconda/3-5.3.1/lib/python3.7/site-packages/docutils-0.14-py3.7.egg-info'
Traceback (most recent call last):
  File "/opt/hpcc/CPU/anaconda/3-5.3.1/lib/python3.7/runpy.py", line 193, in _run_module_as_main
    "__main__", mod_spec)
  File "/opt/hpcc/CPU/anaconda/3-5.3.1/lib/python3.7/runpy.py", line 85, in _run_code
    exec(code, run_globals)
  File "/home/arlan.uy/.local/lib/python3.7/site-packages/pip/__main__.py", line 29, in <module>
    from pip._internal.cli.main import main as _main
  File "/home/arlan.uy/.local/lib/python3.7/site-packages/pip/_internal/cli/main.py", line 9, in <module>
    from pip._internal.cli.autocompletion import autocomplete
  File "/home/arlan.uy/.local/lib/python3.7/site-packages/pip/_internal/cli/autocompletion.py", line 10, in <module>
    from pip._internal.cli.main_parser import create_main_parser
  File "/home/arlan.uy/.local/lib/python3.7/site-packages/pip/_internal/cli/main_parser.py", line 8, in <module>
    from pip._internal.cli import cmdoptions
  File "/home/arlan.uy/.local/lib/python3.7/site-packages/pip/_internal/cli/cmdoptions.py", line 23, in <module>
    from pip._internal.cli.parser import ConfigOptionParser
  File "/home/arlan.uy/.local/lib/python3.7/site-packages/pip/_internal/cli/parser.py", line 12, in <module>
    from pip._internal.configuration import Configuration, ConfigurationError
  File "/home/arlan.uy/.local/lib/python3.7/site-packages/pip/_internal/configuration.py", line 21, in <module>
    from pip._internal.exceptions import (
  File "/home/arlan.uy/.local/lib/python3.7/site-packages/pip/_internal/exceptions.py", line 7, in <module>
    from pip._vendor.pkg_resources import Distribution
  File "/home/arlan.uy/.local/lib/python3.7/site-packages/pip/_vendor/pkg_resources/__init__.py", line 3251, in <module>
    @_call_aside
  File "/home/arlan.uy/.local/lib/python3.7/site-packages/pip/_vendor/pkg_resources/__init__.py", line 3235, in _call_aside
    f(*args, **kwargs)
  File "/home/arlan.uy/.local/lib/python3.7/site-packages/pip/_vendor/pkg_resources/__init__.py", line 3287, in _initialize_master_working_set
    list(map(working_set.add_entry, sys.path))
  File "/home/arlan.uy/.local/lib/python3.7/site-packages/pip/_vendor/pkg_resources/__init__.py", line 623, in add_entry
    for dist in find_distributions(entry, True):
  File "/home/arlan.uy/.local/lib/python3.7/site-packages/pip/_vendor/pkg_resources/__init__.py", line 2065, in find_on_path
    for dist in factory(fullpath):
  File "/home/arlan.uy/.local/lib/python3.7/site-packages/pip/_vendor/pkg_resources/__init__.py", line 2135, in distributions_from_metadata
    root, entry, metadata, precedence=DEVELOP_DIST,
  File "/home/arlan.uy/.local/lib/python3.7/site-packages/pip/_vendor/pkg_resources/__init__.py", line 2592, in from_location
    py_version=py_version, platform=platform, **kw
  File "/home/arlan.uy/.local/lib/python3.7/site-packages/pip/_vendor/pkg_resources/__init__.py", line 2994, in _reload_version
    md_version = self._get_version()
  File "/home/arlan.uy/.local/lib/python3.7/site-packages/pip/_vendor/pkg_resources/__init__.py", line 2772, in _get_version
    version = _version_from_file(lines)
  File "/home/arlan.uy/.local/lib/python3.7/site-packages/pip/_vendor/pkg_resources/__init__.py", line 2556, in _version_from_file
    line = next(iter(version_lines), '')
  File "/home/arlan.uy/.local/lib/python3.7/site-packages/pip/_vendor/pkg_resources/__init__.py", line 2767, in _get_metadata
    for line in self.get_metadata_lines(name):
  File "/home/arlan.uy/.local/lib/python3.7/site-packages/pip/_vendor/pkg_resources/__init__.py", line 1911, in get_metadata_lines
    return yield_lines(self.get_metadata(name))
  File "/home/arlan.uy/.local/lib/python3.7/site-packages/pip/_vendor/pkg_resources/__init__.py", line 1897, in get_metadata
    with io.open(self.path, encoding='utf-8', errors="replace") as f:
OSError: [Errno 5] Input/output error: '/share/hpcc/CPU/anaconda/3-5.3.1/lib/python3.7/site-packages/docutils-0.14-py3.7.egg-info'
Traceback (most recent call last):
  File "/opt/hpcc/CPU/anaconda/3-5.3.1/lib/python3.7/runpy.py", line 193, in _run_module_as_main
    "__main__", mod_spec)
  File "/opt/hpcc/CPU/anaconda/3-5.3.1/lib/python3.7/runpy.py", line 85, in _run_code
    exec(code, run_globals)
  File "/home/arlan.uy/.local/lib/python3.7/site-packages/pip/__main__.py", line 29, in <module>
    from pip._internal.cli.main import main as _main
  File "/home/arlan.uy/.local/lib/python3.7/site-packages/pip/_internal/cli/main.py", line 9, in <module>
    from pip._internal.cli.autocompletion import autocomplete
  File "/home/arlan.uy/.local/lib/python3.7/site-packages/pip/_internal/cli/autocompletion.py", line 10, in <module>
    from pip._internal.cli.main_parser import create_main_parser
  File "/home/arlan.uy/.local/lib/python3.7/site-packages/pip/_internal/cli/main_parser.py", line 8, in <module>
    from pip._internal.cli import cmdoptions
  File "/home/arlan.uy/.local/lib/python3.7/site-packages/pip/_internal/cli/cmdoptions.py", line 23, in <module>
    from pip._internal.cli.parser import ConfigOptionParser
  File "/home/arlan.uy/.local/lib/python3.7/site-packages/pip/_internal/cli/parser.py", line 12, in <module>
    from pip._internal.configuration import Configuration, ConfigurationError
  File "/home/arlan.uy/.local/lib/python3.7/site-packages/pip/_internal/configuration.py", line 21, in <module>
    from pip._internal.exceptions import (
  File "/home/arlan.uy/.local/lib/python3.7/site-packages/pip/_internal/exceptions.py", line 7, in <module>
    from pip._vendor.pkg_resources import Distribution
  File "/home/arlan.uy/.local/lib/python3.7/site-packages/pip/_vendor/pkg_resources/__init__.py", line 3251, in <module>
    @_call_aside
  File "/home/arlan.uy/.local/lib/python3.7/site-packages/pip/_vendor/pkg_resources/__init__.py", line 3235, in _call_aside
    f(*args, **kwargs)
  File "/home/arlan.uy/.local/lib/python3.7/site-packages/pip/_vendor/pkg_resources/__init__.py", line 3287, in _initialize_master_working_set
    list(map(working_set.add_entry, sys.path))
  File "/home/arlan.uy/.local/lib/python3.7/site-packages/pip/_vendor/pkg_resources/__init__.py", line 623, in add_entry
    for dist in find_distributions(entry, True):
  File "/home/arlan.uy/.local/lib/python3.7/site-packages/pip/_vendor/pkg_resources/__init__.py", line 2065, in find_on_path
    for dist in factory(fullpath):
  File "/home/arlan.uy/.local/lib/python3.7/site-packages/pip/_vendor/pkg_resources/__init__.py", line 2135, in distributions_from_metadata
    root, entry, metadata, precedence=DEVELOP_DIST,
  File "/home/arlan.uy/.local/lib/python3.7/site-packages/pip/_vendor/pkg_resources/__init__.py", line 2592, in from_location
    py_version=py_version, platform=platform, **kw
  File "/home/arlan.uy/.local/lib/python3.7/site-packages/pip/_vendor/pkg_resources/__init__.py", line 2994, in _reload_version
    md_version = self._get_version()
  File "/home/arlan.uy/.local/lib/python3.7/site-packages/pip/_vendor/pkg_resources/__init__.py", line 2772, in _get_version
    version = _version_from_file(lines)
  File "/home/arlan.uy/.local/lib/python3.7/site-packages/pip/_vendor/pkg_resources/__init__.py", line 2556, in _version_from_file
    line = next(iter(version_lines), '')
  File "/home/arlan.uy/.local/lib/python3.7/site-packages/pip/_vendor/pkg_resources/__init__.py", line 2767, in _get_metadata
    for line in self.get_metadata_lines(name):
  File "/home/arlan.uy/.local/lib/python3.7/site-packages/pip/_vendor/pkg_resources/__init__.py", line 1911, in get_metadata_lines
    return yield_lines(self.get_metadata(name))
  File "/home/arlan.uy/.local/lib/python3.7/site-packages/pip/_vendor/pkg_resources/__init__.py", line 1898, in get_metadata
    metadata = f.read()
OSError: [Errno 5] Input/output error
srun: error: saliksik-gpu-05: tasks 0-1,3,5-7: Exited with exit code 1
WARNING: Value for scheme.headers does not match. Please report this to <https://github.com/pypa/pip/issues/10151>
distutils: /home/arlan.uy/.local/include/python3.7m/UNKNOWN
sysconfig: /home/arlan.uy/.local/include/python3.7/UNKNOWN
WARNING: Additional context:
user = True
home = None
root = None
prefix = None
WARNING: Value for scheme.headers does not match. Please report this to <https://github.com/pypa/pip/issues/10151>
distutils: /home/arlan.uy/.local/include/python3.7m/UNKNOWN
sysconfig: /home/arlan.uy/.local/include/python3.7/UNKNOWN
WARNING: Additional context:
user = True
home = None
root = None
prefix = None
Traceback (most recent call last):
  File "main.py", line 303, in <module>
    main()
  File "main.py", line 301, in main
    program_main(sys.argv)
  File "main.py", line 95, in program_main
    ga_params = create_empty_yaml(runs, generations, population_size, savefile_name)
  File "main.py", line 24, in create_empty_yaml
    ga_params['run_total'] = runs
TypeError: 'NoneType' object does not support item assignment
srun: error: saliksik-gpu-05: task 1: Exited with exit code 1
Traceback (most recent call last):
  File "main.py", line 303, in <module>
    main()
  File "main.py", line 301, in main
    program_main(sys.argv)
  File "main.py", line 188, in program_main
    gaframework(system, test_cases_path, savefile_name)
  File "/scratch1/scratch2/arlan.uy/ERSSNP_CPU_GPU_Framework/main_dir/src/experimenter_uncommented.py", line 26, in gaframework
    execute_experiment(rssnp, ga, gaeval, ga_params, loadfile_name, start_new, start_from_gen)
  File "/scratch1/scratch2/arlan.uy/ERSSNP_CPU_GPU_Framework/main_dir/src/experimenter_uncommented.py", line 49, in execute_experiment
    gaeval.run(ga, rssnp, stats_run['population_size'], stats_run['fitness_function'],  gaeval.no_of_run, gaeval.no_of_gen, stats_run['mutation_rate'], loadfile_name, stats_run['selection_func'], start_new, start_from_gen)
  File "/scratch1/scratch2/arlan.uy/ERSSNP_CPU_GPU_Framework/main_dir/src/abstracts/GAevaluator_integ.py", line 38, in run
    run_fitness = genetic_algo.simulate(system, size, function, generations, mutation_rate, path_name, run, selection_func, start_from_gen)            
  File "/scratch1/scratch2/arlan.uy/ERSSNP_CPU_GPU_Framework/main_dir/src/abstracts/geneticalgo_integ.py", line 303, in simulate
    self.evaluate(chrom, function)
  File "/scratch1/scratch2/arlan.uy/ERSSNP_CPU_GPU_Framework/main_dir/src/abstracts/geneticalgo_integ.py", line 248, in evaluate
    value = assign_fitness(chromosome['system'].out_spiketrain, pair['output'], function)
  File "/scratch1/scratch2/arlan.uy/ERSSNP_CPU_GPU_Framework/main_dir/src/abstracts/geneticalgo_integ.py", line 43, in assign_fitness
    result = edit_distance2(string_format(generated), string_format(actual))
  File "/scratch1/scratch2/arlan.uy/ERSSNP_CPU_GPU_Framework/main_dir/src/abstracts/fitness.py", line 116, in edit_distance2
    timer_write("Evaluate", start, finish)
  File "/scratch1/scratch2/arlan.uy/ERSSNP_CPU_GPU_Framework/main_dir/src/abstracts/cpu_timer.py", line 29, in timer_write
    timer_params['run_indexes'][run_index_state][ga_name] += finish - start
TypeError: 'NoneType' object is not subscriptable
Traceback (most recent call last):
  File "main.py", line 303, in <module>
    main()
  File "main.py", line 301, in main
    program_main(sys.argv)
  File "main.py", line 188, in program_main
    gaframework(system, test_cases_path, savefile_name)
  File "/scratch1/scratch2/arlan.uy/ERSSNP_CPU_GPU_Framework/main_dir/src/experimenter_uncommented.py", line 26, in gaframework
    execute_experiment(rssnp, ga, gaeval, ga_params, loadfile_name, start_new, start_from_gen)
  File "/scratch1/scratch2/arlan.uy/ERSSNP_CPU_GPU_Framework/main_dir/src/experimenter_uncommented.py", line 49, in execute_experiment
    gaeval.run(ga, rssnp, stats_run['population_size'], stats_run['fitness_function'],  gaeval.no_of_run, gaeval.no_of_gen, stats_run['mutation_rate'], loadfile_name, stats_run['selection_func'], start_new, start_from_gen)
  File "/scratch1/scratch2/arlan.uy/ERSSNP_CPU_GPU_Framework/main_dir/src/abstracts/GAevaluator_integ.py", line 38, in run
    run_fitness = genetic_algo.simulate(system, size, function, generations, mutation_rate, path_name, run, selection_func, start_from_gen)            
  File "/scratch1/scratch2/arlan.uy/ERSSNP_CPU_GPU_Framework/main_dir/src/abstracts/geneticalgo_integ.py", line 273, in simulate
    timer_write_run(run_index)
  File "/scratch1/scratch2/arlan.uy/ERSSNP_CPU_GPU_Framework/main_dir/src/abstracts/cpu_timer.py", line 36, in timer_write_run
    timer_params['run_indexes'][run_index_state] = {}
TypeError: 'NoneType' object is not subscriptable
srun: error: saliksik-gpu-05: tasks 0,4: Exited with exit code 1
Traceback (most recent call last):
  File "main.py", line 303, in <module>
    main()
  File "main.py", line 301, in main
    program_main(sys.argv)
  File "main.py", line 188, in program_main
    gaframework(system, test_cases_path, savefile_name)
  File "/scratch1/scratch2/arlan.uy/ERSSNP_CPU_GPU_Framework/main_dir/src/experimenter_uncommented.py", line 26, in gaframework
    execute_experiment(rssnp, ga, gaeval, ga_params, loadfile_name, start_new, start_from_gen)
  File "/scratch1/scratch2/arlan.uy/ERSSNP_CPU_GPU_Framework/main_dir/src/experimenter_uncommented.py", line 49, in execute_experiment
    gaeval.run(ga, rssnp, stats_run['population_size'], stats_run['fitness_function'],  gaeval.no_of_run, gaeval.no_of_gen, stats_run['mutation_rate'], loadfile_name, stats_run['selection_func'], start_new, start_from_gen)
  File "/scratch1/scratch2/arlan.uy/ERSSNP_CPU_GPU_Framework/main_dir/src/abstracts/GAevaluator_integ.py", line 38, in run
    run_fitness = genetic_algo.simulate(system, size, function, generations, mutation_rate, path_name, run, selection_func, start_from_gen)            
  File "/scratch1/scratch2/arlan.uy/ERSSNP_CPU_GPU_Framework/main_dir/src/abstracts/geneticalgo_integ.py", line 303, in simulate
    self.evaluate(chrom, function)
  File "/scratch1/scratch2/arlan.uy/ERSSNP_CPU_GPU_Framework/main_dir/src/abstracts/geneticalgo_integ.py", line 248, in evaluate
    value = assign_fitness(chromosome['system'].out_spiketrain, pair['output'], function)
  File "/scratch1/scratch2/arlan.uy/ERSSNP_CPU_GPU_Framework/main_dir/src/abstracts/geneticalgo_integ.py", line 43, in assign_fitness
    result = edit_distance2(string_format(generated), string_format(actual))
  File "/scratch1/scratch2/arlan.uy/ERSSNP_CPU_GPU_Framework/main_dir/src/abstracts/fitness.py", line 116, in edit_distance2
    timer_write("Evaluate", start, finish)
  File "/scratch1/scratch2/arlan.uy/ERSSNP_CPU_GPU_Framework/main_dir/src/abstracts/cpu_timer.py", line 29, in timer_write
    timer_params['run_indexes'][run_index_state][ga_name] += finish - start
TypeError: 'NoneType' object is not subscriptable
Traceback (most recent call last):
  File "main.py", line 303, in <module>
    main()
  File "main.py", line 301, in main
    program_main(sys.argv)
  File "main.py", line 188, in program_main
    gaframework(system, test_cases_path, savefile_name)
  File "/scratch1/scratch2/arlan.uy/ERSSNP_CPU_GPU_Framework/main_dir/src/experimenter_uncommented.py", line 26, in gaframework
    execute_experiment(rssnp, ga, gaeval, ga_params, loadfile_name, start_new, start_from_gen)
  File "/scratch1/scratch2/arlan.uy/ERSSNP_CPU_GPU_Framework/main_dir/src/experimenter_uncommented.py", line 49, in execute_experiment
    gaeval.run(ga, rssnp, stats_run['population_size'], stats_run['fitness_function'],  gaeval.no_of_run, gaeval.no_of_gen, stats_run['mutation_rate'], loadfile_name, stats_run['selection_func'], start_new, start_from_gen)
  File "/scratch1/scratch2/arlan.uy/ERSSNP_CPU_GPU_Framework/main_dir/src/abstracts/GAevaluator_integ.py", line 38, in run
    run_fitness = genetic_algo.simulate(system, size, function, generations, mutation_rate, path_name, run, selection_func, start_from_gen)            
  File "/scratch1/scratch2/arlan.uy/ERSSNP_CPU_GPU_Framework/main_dir/src/abstracts/geneticalgo_integ.py", line 303, in simulate
    self.evaluate(chrom, function)
  File "/scratch1/scratch2/arlan.uy/ERSSNP_CPU_GPU_Framework/main_dir/src/abstracts/geneticalgo_integ.py", line 248, in evaluate
    value = assign_fitness(chromosome['system'].out_spiketrain, pair['output'], function)
  File "/scratch1/scratch2/arlan.uy/ERSSNP_CPU_GPU_Framework/main_dir/src/abstracts/geneticalgo_integ.py", line 43, in assign_fitness
    result = edit_distance2(string_format(generated), string_format(actual))
  File "/scratch1/scratch2/arlan.uy/ERSSNP_CPU_GPU_Framework/main_dir/src/abstracts/fitness.py", line 116, in edit_distance2
    timer_write("Evaluate", start, finish)
  File "/scratch1/scratch2/arlan.uy/ERSSNP_CPU_GPU_Framework/main_dir/src/abstracts/cpu_timer.py", line 29, in timer_write
    timer_params['run_indexes'][run_index_state][ga_name] += finish - start
TypeError: 'NoneType' object is not subscriptable
Traceback (most recent call last):
  File "main.py", line 303, in <module>
    main()
  File "main.py", line 301, in main
    program_main(sys.argv)
  File "main.py", line 188, in program_main
    gaframework(system, test_cases_path, savefile_name)
  File "/scratch1/scratch2/arlan.uy/ERSSNP_CPU_GPU_Framework/main_dir/src/experimenter_uncommented.py", line 26, in gaframework
    execute_experiment(rssnp, ga, gaeval, ga_params, loadfile_name, start_new, start_from_gen)
  File "/scratch1/scratch2/arlan.uy/ERSSNP_CPU_GPU_Framework/main_dir/src/experimenter_uncommented.py", line 49, in execute_experiment
    gaeval.run(ga, rssnp, stats_run['population_size'], stats_run['fitness_function'],  gaeval.no_of_run, gaeval.no_of_gen, stats_run['mutation_rate'], loadfile_name, stats_run['selection_func'], start_new, start_from_gen)
  File "/scratch1/scratch2/arlan.uy/ERSSNP_CPU_GPU_Framework/main_dir/src/abstracts/GAevaluator_integ.py", line 38, in run
    run_fitness = genetic_algo.simulate(system, size, function, generations, mutation_rate, path_name, run, selection_func, start_from_gen)            
  File "/scratch1/scratch2/arlan.uy/ERSSNP_CPU_GPU_Framework/main_dir/src/abstracts/geneticalgo_integ.py", line 303, in simulate
    self.evaluate(chrom, function)
  File "/scratch1/scratch2/arlan.uy/ERSSNP_CPU_GPU_Framework/main_dir/src/abstracts/geneticalgo_integ.py", line 248, in evaluate
    value = assign_fitness(chromosome['system'].out_spiketrain, pair['output'], function)
  File "/scratch1/scratch2/arlan.uy/ERSSNP_CPU_GPU_Framework/main_dir/src/abstracts/geneticalgo_integ.py", line 43, in assign_fitness
    result = edit_distance2(string_format(generated), string_format(actual))
  File "/scratch1/scratch2/arlan.uy/ERSSNP_CPU_GPU_Framework/main_dir/src/abstracts/fitness.py", line 116, in edit_distance2
    timer_write("Evaluate", start, finish)
  File "/scratch1/scratch2/arlan.uy/ERSSNP_CPU_GPU_Framework/main_dir/src/abstracts/cpu_timer.py", line 29, in timer_write
    timer_params['run_indexes'][run_index_state][ga_name] += finish - start
TypeError: 'NoneType' object is not subscriptable
Traceback (most recent call last):
  File "main.py", line 303, in <module>
    main()
  File "main.py", line 301, in main
    program_main(sys.argv)
  File "main.py", line 188, in program_main
    gaframework(system, test_cases_path, savefile_name)
  File "/scratch1/scratch2/arlan.uy/ERSSNP_CPU_GPU_Framework/main_dir/src/experimenter_uncommented.py", line 26, in gaframework
    execute_experiment(rssnp, ga, gaeval, ga_params, loadfile_name, start_new, start_from_gen)
  File "/scratch1/scratch2/arlan.uy/ERSSNP_CPU_GPU_Framework/main_dir/src/experimenter_uncommented.py", line 49, in execute_experiment
    gaeval.run(ga, rssnp, stats_run['population_size'], stats_run['fitness_function'],  gaeval.no_of_run, gaeval.no_of_gen, stats_run['mutation_rate'], loadfile_name, stats_run['selection_func'], start_new, start_from_gen)
  File "/scratch1/scratch2/arlan.uy/ERSSNP_CPU_GPU_Framework/main_dir/src/abstracts/GAevaluator_integ.py", line 38, in run
    run_fitness = genetic_algo.simulate(system, size, function, generations, mutation_rate, path_name, run, selection_func, start_from_gen)            
  File "/scratch1/scratch2/arlan.uy/ERSSNP_CPU_GPU_Framework/main_dir/src/abstracts/geneticalgo_integ.py", line 303, in simulate
    self.evaluate(chrom, function)
  File "/scratch1/scratch2/arlan.uy/ERSSNP_CPU_GPU_Framework/main_dir/src/abstracts/geneticalgo_integ.py", line 248, in evaluate
    value = assign_fitness(chromosome['system'].out_spiketrain, pair['output'], function)
  File "/scratch1/scratch2/arlan.uy/ERSSNP_CPU_GPU_Framework/main_dir/src/abstracts/geneticalgo_integ.py", line 43, in assign_fitness
    result = edit_distance2(string_format(generated), string_format(actual))
  File "/scratch1/scratch2/arlan.uy/ERSSNP_CPU_GPU_Framework/main_dir/src/abstracts/fitness.py", line 116, in edit_distance2
    timer_write("Evaluate", start, finish)
  File "/scratch1/scratch2/arlan.uy/ERSSNP_CPU_GPU_Framework/main_dir/src/abstracts/cpu_timer.py", line 29, in timer_write
    timer_params['run_indexes'][run_index_state][ga_name] += finish - start
TypeError: 'NoneType' object is not subscriptable
srun: error: saliksik-gpu-05: tasks 2-3,5-6: Exited with exit code 1
