>> anaconda-3-5.3.1 has been loaded.
>> python-3.8.2 has been loaded.
>> cuda-10.1_cudnn-7.6.5 has been loaded.
Traceback (most recent call last):
  File "/opt/hpcc/CPU/anaconda/3-5.3.1/lib/python3.7/runpy.py", line 193, in _run_module_as_main
    "__main__", mod_spec)
  File "/opt/hpcc/CPU/anaconda/3-5.3.1/lib/python3.7/runpy.py", line 85, in _run_code
    exec(code, run_globals)
  File "/home/arlan.uy/.local/lib/python3.7/site-packages/pip/__main__.py", line 29, in <module>
    from pip._internal.cli.main import main as _main
  File "/home/arlan.uy/.local/lib/python3.7/site-packages/pip/_internal/cli/main.py", line 9, in <module>
    from pip._internal.cli.autocompletion import autocomplete
  File "/home/arlan.uy/.local/lib/python3.7/site-packages/pip/_internal/cli/autocompletion.py", line 10, in <module>
    from pip._internal.cli.main_parser import create_main_parser
  File "/home/arlan.uy/.local/lib/python3.7/site-packages/pip/_internal/cli/main_parser.py", line 8, in <module>
    from pip._internal.cli import cmdoptions
  File "/home/arlan.uy/.local/lib/python3.7/site-packages/pip/_internal/cli/cmdoptions.py", line 23, in <module>
    from pip._internal.cli.parser import ConfigOptionParser
  File "/home/arlan.uy/.local/lib/python3.7/site-packages/pip/_internal/cli/parser.py", line 12, in <module>
    from pip._internal.configuration import Configuration, ConfigurationError
  File "/home/arlan.uy/.local/lib/python3.7/site-packages/pip/_internal/configuration.py", line 21, in <module>
    from pip._internal.exceptions import (
  File "/home/arlan.uy/.local/lib/python3.7/site-packages/pip/_internal/exceptions.py", line 8, in <module>
    from pip._vendor.requests.models import Request, Response
  File "/home/arlan.uy/.local/lib/python3.7/site-packages/pip/_vendor/requests/__init__.py", line 43, in <module>
    from pip._vendor import urllib3
  File "/home/arlan.uy/.local/lib/python3.7/site-packages/pip/_vendor/urllib3/__init__.py", line 13, in <module>
    from .connectionpool import HTTPConnectionPool, HTTPSConnectionPool, connection_from_url
  File "/home/arlan.uy/.local/lib/python3.7/site-packages/pip/_vendor/urllib3/connectionpool.py", line 40, in <module>
    from .response import HTTPResponse
  File "/home/arlan.uy/.local/lib/python3.7/site-packages/pip/_vendor/urllib3/response.py", line 5, in <module>
    import zlib
ImportError: /opt/hpcc/CPU/anaconda/3-5.3.1/lib/python3.7/lib-dynload/zlib.cpython-37m-x86_64-linux-gnu.so: cannot open shared object file: Input/output error
Traceback (most recent call last):
  File "/opt/hpcc/CPU/anaconda/3-5.3.1/lib/python3.7/runpy.py", line 193, in _run_module_as_main
    "__main__", mod_spec)
  File "/opt/hpcc/CPU/anaconda/3-5.3.1/lib/python3.7/runpy.py", line 85, in _run_code
    exec(code, run_globals)
  File "/home/arlan.uy/.local/lib/python3.7/site-packages/pip/__main__.py", line 29, in <module>
    from pip._internal.cli.main import main as _main
  File "/home/arlan.uy/.local/lib/python3.7/site-packages/pip/_internal/cli/main.py", line 9, in <module>
    from pip._internal.cli.autocompletion import autocomplete
  File "/home/arlan.uy/.local/lib/python3.7/site-packages/pip/_internal/cli/autocompletion.py", line 10, in <module>
    from pip._internal.cli.main_parser import create_main_parser
  File "/home/arlan.uy/.local/lib/python3.7/site-packages/pip/_internal/cli/main_parser.py", line 8, in <module>
    from pip._internal.cli import cmdoptions
  File "/home/arlan.uy/.local/lib/python3.7/site-packages/pip/_internal/cli/cmdoptions.py", line 23, in <module>
    from pip._internal.cli.parser import ConfigOptionParser
  File "/home/arlan.uy/.local/lib/python3.7/site-packages/pip/_internal/cli/parser.py", line 12, in <module>
    from pip._internal.configuration import Configuration, ConfigurationError
  File "/home/arlan.uy/.local/lib/python3.7/site-packages/pip/_internal/configuration.py", line 21, in <module>
    from pip._internal.exceptions import (
  File "/home/arlan.uy/.local/lib/python3.7/site-packages/pip/_internal/exceptions.py", line 8, in <module>
    from pip._vendor.requests.models import Request, Response
  File "/home/arlan.uy/.local/lib/python3.7/site-packages/pip/_vendor/requests/__init__.py", line 43, in <module>
    from pip._vendor import urllib3
  File "/home/arlan.uy/.local/lib/python3.7/site-packages/pip/_vendor/urllib3/__init__.py", line 13, in <module>
    from .connectionpool import HTTPConnectionPool, HTTPSConnectionPool, connection_from_url
  File "/home/arlan.uy/.local/lib/python3.7/site-packages/pip/_vendor/urllib3/connectionpool.py", line 40, in <module>
    from .response import HTTPResponse
  File "/home/arlan.uy/.local/lib/python3.7/site-packages/pip/_vendor/urllib3/response.py", line 5, in <module>
    import zlib
ImportError: /opt/hpcc/CPU/anaconda/3-5.3.1/lib/python3.7/lib-dynload/zlib.cpython-37m-x86_64-linux-gnu.so: cannot open shared object file: Input/output error
Traceback (most recent call last):
  File "/opt/hpcc/CPU/anaconda/3-5.3.1/lib/python3.7/runpy.py", line 193, in _run_module_as_main
    "__main__", mod_spec)
  File "/opt/hpcc/CPU/anaconda/3-5.3.1/lib/python3.7/runpy.py", line 85, in _run_code
    exec(code, run_globals)
  File "/home/arlan.uy/.local/lib/python3.7/site-packages/pip/__main__.py", line 29, in <module>
    from pip._internal.cli.main import main as _main
  File "/home/arlan.uy/.local/lib/python3.7/site-packages/pip/_internal/cli/main.py", line 9, in <module>
    from pip._internal.cli.autocompletion import autocomplete
  File "/home/arlan.uy/.local/lib/python3.7/site-packages/pip/_internal/cli/autocompletion.py", line 10, in <module>
    from pip._internal.cli.main_parser import create_main_parser
  File "/home/arlan.uy/.local/lib/python3.7/site-packages/pip/_internal/cli/main_parser.py", line 8, in <module>
    from pip._internal.cli import cmdoptions
  File "/home/arlan.uy/.local/lib/python3.7/site-packages/pip/_internal/cli/cmdoptions.py", line 23, in <module>
    from pip._internal.cli.parser import ConfigOptionParser
  File "/home/arlan.uy/.local/lib/python3.7/site-packages/pip/_internal/cli/parser.py", line 12, in <module>
    from pip._internal.configuration import Configuration, ConfigurationError
  File "/home/arlan.uy/.local/lib/python3.7/site-packages/pip/_internal/configuration.py", line 21, in <module>
    from pip._internal.exceptions import (
  File "/home/arlan.uy/.local/lib/python3.7/site-packages/pip/_internal/exceptions.py", line 8, in <module>
    from pip._vendor.requests.models import Request, Response
  File "/home/arlan.uy/.local/lib/python3.7/site-packages/pip/_vendor/requests/__init__.py", line 43, in <module>
    from pip._vendor import urllib3
  File "/home/arlan.uy/.local/lib/python3.7/site-packages/pip/_vendor/urllib3/__init__.py", line 13, in <module>
    from .connectionpool import HTTPConnectionPool, HTTPSConnectionPool, connection_from_url
  File "/home/arlan.uy/.local/lib/python3.7/site-packages/pip/_vendor/urllib3/connectionpool.py", line 40, in <module>
    from .response import HTTPResponse
  File "/home/arlan.uy/.local/lib/python3.7/site-packages/pip/_vendor/urllib3/response.py", line 5, in <module>
    import zlib
ImportError: /opt/hpcc/CPU/anaconda/3-5.3.1/lib/python3.7/lib-dynload/zlib.cpython-37m-x86_64-linux-gnu.so: cannot open shared object file: Input/output error
Traceback (most recent call last):
  File "/opt/hpcc/CPU/anaconda/3-5.3.1/lib/python3.7/runpy.py", line 193, in _run_module_as_main
    "__main__", mod_spec)
  File "/opt/hpcc/CPU/anaconda/3-5.3.1/lib/python3.7/runpy.py", line 85, in _run_code
    exec(code, run_globals)
  File "/home/arlan.uy/.local/lib/python3.7/site-packages/pip/__main__.py", line 29, in <module>
    from pip._internal.cli.main import main as _main
  File "/home/arlan.uy/.local/lib/python3.7/site-packages/pip/_internal/cli/main.py", line 9, in <module>
    from pip._internal.cli.autocompletion import autocomplete
  File "/home/arlan.uy/.local/lib/python3.7/site-packages/pip/_internal/cli/autocompletion.py", line 10, in <module>
    from pip._internal.cli.main_parser import create_main_parser
  File "/home/arlan.uy/.local/lib/python3.7/site-packages/pip/_internal/cli/main_parser.py", line 8, in <module>
    from pip._internal.cli import cmdoptions
  File "/home/arlan.uy/.local/lib/python3.7/site-packages/pip/_internal/cli/cmdoptions.py", line 23, in <module>
    from pip._internal.cli.parser import ConfigOptionParser
  File "/home/arlan.uy/.local/lib/python3.7/site-packages/pip/_internal/cli/parser.py", line 12, in <module>
    from pip._internal.configuration import Configuration, ConfigurationError
  File "/home/arlan.uy/.local/lib/python3.7/site-packages/pip/_internal/configuration.py", line 21, in <module>
    from pip._internal.exceptions import (
  File "/home/arlan.uy/.local/lib/python3.7/site-packages/pip/_internal/exceptions.py", line 8, in <module>
    from pip._vendor.requests.models import Request, Response
  File "/home/arlan.uy/.local/lib/python3.7/site-packages/pip/_vendor/requests/__init__.py", line 43, in <module>
    from pip._vendor import urllib3
  File "/home/arlan.uy/.local/lib/python3.7/site-packages/pip/_vendor/urllib3/__init__.py", line 13, in <module>
    from .connectionpool import HTTPConnectionPool, HTTPSConnectionPool, connection_from_url
  File "/home/arlan.uy/.local/lib/python3.7/site-packages/pip/_vendor/urllib3/connectionpool.py", line 40, in <module>
    from .response import HTTPResponse
  File "/home/arlan.uy/.local/lib/python3.7/site-packages/pip/_vendor/urllib3/response.py", line 5, in <module>
    import zlib
ImportError: /opt/hpcc/CPU/anaconda/3-5.3.1/lib/python3.7/lib-dynload/zlib.cpython-37m-x86_64-linux-gnu.so: cannot open shared object file: Input/output error
Traceback (most recent call last):
  File "/opt/hpcc/CPU/anaconda/3-5.3.1/lib/python3.7/runpy.py", line 193, in _run_module_as_main
    "__main__", mod_spec)
  File "/opt/hpcc/CPU/anaconda/3-5.3.1/lib/python3.7/runpy.py", line 85, in _run_code
    exec(code, run_globals)
  File "/home/arlan.uy/.local/lib/python3.7/site-packages/pip/__main__.py", line 29, in <module>
    from pip._internal.cli.main import main as _main
  File "/home/arlan.uy/.local/lib/python3.7/site-packages/pip/_internal/cli/main.py", line 9, in <module>
    from pip._internal.cli.autocompletion import autocomplete
  File "/home/arlan.uy/.local/lib/python3.7/site-packages/pip/_internal/cli/autocompletion.py", line 10, in <module>
    from pip._internal.cli.main_parser import create_main_parser
  File "/home/arlan.uy/.local/lib/python3.7/site-packages/pip/_internal/cli/main_parser.py", line 8, in <module>
    from pip._internal.cli import cmdoptions
  File "/home/arlan.uy/.local/lib/python3.7/site-packages/pip/_internal/cli/cmdoptions.py", line 23, in <module>
    from pip._internal.cli.parser import ConfigOptionParser
  File "/home/arlan.uy/.local/lib/python3.7/site-packages/pip/_internal/cli/parser.py", line 12, in <module>
    from pip._internal.configuration import Configuration, ConfigurationError
  File "/home/arlan.uy/.local/lib/python3.7/site-packages/pip/_internal/configuration.py", line 21, in <module>
    from pip._internal.exceptions import (
  File "/home/arlan.uy/.local/lib/python3.7/site-packages/pip/_internal/exceptions.py", line 8, in <module>
    from pip._vendor.requests.models import Request, Response
  File "/home/arlan.uy/.local/lib/python3.7/site-packages/pip/_vendor/requests/__init__.py", line 43, in <module>
    from pip._vendor import urllib3
  File "/home/arlan.uy/.local/lib/python3.7/site-packages/pip/_vendor/urllib3/__init__.py", line 13, in <module>
    from .connectionpool import HTTPConnectionPool, HTTPSConnectionPool, connection_from_url
  File "/home/arlan.uy/.local/lib/python3.7/site-packages/pip/_vendor/urllib3/connectionpool.py", line 40, in <module>
    from .response import HTTPResponse
  File "/home/arlan.uy/.local/lib/python3.7/site-packages/pip/_vendor/urllib3/response.py", line 5, in <module>
    import zlib
ImportError: /opt/hpcc/CPU/anaconda/3-5.3.1/lib/python3.7/lib-dynload/zlib.cpython-37m-x86_64-linux-gnu.so: cannot open shared object file: Input/output error
Traceback (most recent call last):
  File "/opt/hpcc/CPU/anaconda/3-5.3.1/lib/python3.7/runpy.py", line 193, in _run_module_as_main
    "__main__", mod_spec)
  File "/opt/hpcc/CPU/anaconda/3-5.3.1/lib/python3.7/runpy.py", line 85, in _run_code
    exec(code, run_globals)
  File "/home/arlan.uy/.local/lib/python3.7/site-packages/pip/__main__.py", line 29, in <module>
    from pip._internal.cli.main import main as _main
  File "/home/arlan.uy/.local/lib/python3.7/site-packages/pip/_internal/cli/main.py", line 9, in <module>
    from pip._internal.cli.autocompletion import autocomplete
  File "/home/arlan.uy/.local/lib/python3.7/site-packages/pip/_internal/cli/autocompletion.py", line 10, in <module>
    from pip._internal.cli.main_parser import create_main_parser
  File "/home/arlan.uy/.local/lib/python3.7/site-packages/pip/_internal/cli/main_parser.py", line 8, in <module>
    from pip._internal.cli import cmdoptions
  File "/home/arlan.uy/.local/lib/python3.7/site-packages/pip/_internal/cli/cmdoptions.py", line 23, in <module>
    from pip._internal.cli.parser import ConfigOptionParser
  File "/home/arlan.uy/.local/lib/python3.7/site-packages/pip/_internal/cli/parser.py", line 12, in <module>
    from pip._internal.configuration import Configuration, ConfigurationError
  File "/home/arlan.uy/.local/lib/python3.7/site-packages/pip/_internal/configuration.py", line 21, in <module>
    from pip._internal.exceptions import (
  File "/home/arlan.uy/.local/lib/python3.7/site-packages/pip/_internal/exceptions.py", line 8, in <module>
    from pip._vendor.requests.models import Request, Response
  File "/home/arlan.uy/.local/lib/python3.7/site-packages/pip/_vendor/requests/__init__.py", line 43, in <module>
    from pip._vendor import urllib3
  File "/home/arlan.uy/.local/lib/python3.7/site-packages/pip/_vendor/urllib3/__init__.py", line 13, in <module>
    from .connectionpool import HTTPConnectionPool, HTTPSConnectionPool, connection_from_url
  File "/home/arlan.uy/.local/lib/python3.7/site-packages/pip/_vendor/urllib3/connectionpool.py", line 40, in <module>
    from .response import HTTPResponse
  File "/home/arlan.uy/.local/lib/python3.7/site-packages/pip/_vendor/urllib3/response.py", line 5, in <module>
    import zlib
ImportError: /opt/hpcc/CPU/anaconda/3-5.3.1/lib/python3.7/lib-dynload/zlib.cpython-37m-x86_64-linux-gnu.so: cannot open shared object file: Input/output error
Traceback (most recent call last):
  File "/opt/hpcc/CPU/anaconda/3-5.3.1/lib/python3.7/runpy.py", line 193, in _run_module_as_main
    "__main__", mod_spec)
  File "/opt/hpcc/CPU/anaconda/3-5.3.1/lib/python3.7/runpy.py", line 85, in _run_code
    exec(code, run_globals)
  File "/home/arlan.uy/.local/lib/python3.7/site-packages/pip/__main__.py", line 29, in <module>
    from pip._internal.cli.main import main as _main
  File "/home/arlan.uy/.local/lib/python3.7/site-packages/pip/_internal/cli/main.py", line 9, in <module>
    from pip._internal.cli.autocompletion import autocomplete
  File "/home/arlan.uy/.local/lib/python3.7/site-packages/pip/_internal/cli/autocompletion.py", line 10, in <module>
    from pip._internal.cli.main_parser import create_main_parser
  File "/home/arlan.uy/.local/lib/python3.7/site-packages/pip/_internal/cli/main_parser.py", line 8, in <module>
    from pip._internal.cli import cmdoptions
  File "/home/arlan.uy/.local/lib/python3.7/site-packages/pip/_internal/cli/cmdoptions.py", line 23, in <module>
    from pip._internal.cli.parser import ConfigOptionParser
  File "/home/arlan.uy/.local/lib/python3.7/site-packages/pip/_internal/cli/parser.py", line 12, in <module>
    from pip._internal.configuration import Configuration, ConfigurationError
  File "/home/arlan.uy/.local/lib/python3.7/site-packages/pip/_internal/configuration.py", line 21, in <module>
    from pip._internal.exceptions import (
  File "/home/arlan.uy/.local/lib/python3.7/site-packages/pip/_internal/exceptions.py", line 8, in <module>
    from pip._vendor.requests.models import Request, Response
  File "/home/arlan.uy/.local/lib/python3.7/site-packages/pip/_vendor/requests/__init__.py", line 43, in <module>
    from pip._vendor import urllib3
  File "/home/arlan.uy/.local/lib/python3.7/site-packages/pip/_vendor/urllib3/__init__.py", line 13, in <module>
    from .connectionpool import HTTPConnectionPool, HTTPSConnectionPool, connection_from_url
  File "/home/arlan.uy/.local/lib/python3.7/site-packages/pip/_vendor/urllib3/connectionpool.py", line 40, in <module>
    from .response import HTTPResponse
  File "/home/arlan.uy/.local/lib/python3.7/site-packages/pip/_vendor/urllib3/response.py", line 5, in <module>
    import zlib
ImportError: /opt/hpcc/CPU/anaconda/3-5.3.1/lib/python3.7/lib-dynload/zlib.cpython-37m-x86_64-linux-gnu.so: cannot open shared object file: Input/output error
Traceback (most recent call last):
  File "/opt/hpcc/CPU/anaconda/3-5.3.1/lib/python3.7/runpy.py", line 193, in _run_module_as_main
    "__main__", mod_spec)
  File "/opt/hpcc/CPU/anaconda/3-5.3.1/lib/python3.7/runpy.py", line 85, in _run_code
    exec(code, run_globals)
  File "/home/arlan.uy/.local/lib/python3.7/site-packages/pip/__main__.py", line 29, in <module>
    from pip._internal.cli.main import main as _main
  File "/home/arlan.uy/.local/lib/python3.7/site-packages/pip/_internal/cli/main.py", line 9, in <module>
    from pip._internal.cli.autocompletion import autocomplete
  File "/home/arlan.uy/.local/lib/python3.7/site-packages/pip/_internal/cli/autocompletion.py", line 10, in <module>
    from pip._internal.cli.main_parser import create_main_parser
  File "/home/arlan.uy/.local/lib/python3.7/site-packages/pip/_internal/cli/main_parser.py", line 8, in <module>
    from pip._internal.cli import cmdoptions
  File "/home/arlan.uy/.local/lib/python3.7/site-packages/pip/_internal/cli/cmdoptions.py", line 23, in <module>
    from pip._internal.cli.parser import ConfigOptionParser
  File "/home/arlan.uy/.local/lib/python3.7/site-packages/pip/_internal/cli/parser.py", line 12, in <module>
    from pip._internal.configuration import Configuration, ConfigurationError
  File "/home/arlan.uy/.local/lib/python3.7/site-packages/pip/_internal/configuration.py", line 21, in <module>
    from pip._internal.exceptions import (
  File "/home/arlan.uy/.local/lib/python3.7/site-packages/pip/_internal/exceptions.py", line 8, in <module>
    from pip._vendor.requests.models import Request, Response
  File "/home/arlan.uy/.local/lib/python3.7/site-packages/pip/_vendor/requests/__init__.py", line 43, in <module>
    from pip._vendor import urllib3
  File "/home/arlan.uy/.local/lib/python3.7/site-packages/pip/_vendor/urllib3/__init__.py", line 13, in <module>
    from .connectionpool import HTTPConnectionPool, HTTPSConnectionPool, connection_from_url
  File "/home/arlan.uy/.local/lib/python3.7/site-packages/pip/_vendor/urllib3/connectionpool.py", line 40, in <module>
    from .response import HTTPResponse
  File "/home/arlan.uy/.local/lib/python3.7/site-packages/pip/_vendor/urllib3/response.py", line 5, in <module>
    import zlib
ImportError: /opt/hpcc/CPU/anaconda/3-5.3.1/lib/python3.7/lib-dynload/zlib.cpython-37m-x86_64-linux-gnu.so: cannot open shared object file: Input/output error
Traceback (most recent call last):
  File "/opt/hpcc/CPU/anaconda/3-5.3.1/lib/python3.7/runpy.py", line 193, in _run_module_as_main
    "__main__", mod_spec)
  File "/opt/hpcc/CPU/anaconda/3-5.3.1/lib/python3.7/runpy.py", line 85, in _run_code
    exec(code, run_globals)
  File "/home/arlan.uy/.local/lib/python3.7/site-packages/pip/__main__.py", line 29, in <module>
    from pip._internal.cli.main import main as _main
  File "/home/arlan.uy/.local/lib/python3.7/site-packages/pip/_internal/cli/main.py", line 9, in <module>
    from pip._internal.cli.autocompletion import autocomplete
  File "/home/arlan.uy/.local/lib/python3.7/site-packages/pip/_internal/cli/autocompletion.py", line 10, in <module>
    from pip._internal.cli.main_parser import create_main_parser
  File "/home/arlan.uy/.local/lib/python3.7/site-packages/pip/_internal/cli/main_parser.py", line 8, in <module>
    from pip._internal.cli import cmdoptions
  File "/home/arlan.uy/.local/lib/python3.7/site-packages/pip/_internal/cli/cmdoptions.py", line 23, in <module>
    from pip._internal.cli.parser import ConfigOptionParser
  File "/home/arlan.uy/.local/lib/python3.7/site-packages/pip/_internal/cli/parser.py", line 12, in <module>
    from pip._internal.configuration import Configuration, ConfigurationError
  File "/home/arlan.uy/.local/lib/python3.7/site-packages/pip/_internal/configuration.py", line 21, in <module>
    from pip._internal.exceptions import (
  File "/home/arlan.uy/.local/lib/python3.7/site-packages/pip/_internal/exceptions.py", line 8, in <module>
    from pip._vendor.requests.models import Request, Response
  File "/home/arlan.uy/.local/lib/python3.7/site-packages/pip/_vendor/requests/__init__.py", line 43, in <module>
    from pip._vendor import urllib3
  File "/home/arlan.uy/.local/lib/python3.7/site-packages/pip/_vendor/urllib3/__init__.py", line 13, in <module>
    from .connectionpool import HTTPConnectionPool, HTTPSConnectionPool, connection_from_url
  File "/home/arlan.uy/.local/lib/python3.7/site-packages/pip/_vendor/urllib3/connectionpool.py", line 40, in <module>
    from .response import HTTPResponse
  File "/home/arlan.uy/.local/lib/python3.7/site-packages/pip/_vendor/urllib3/response.py", line 5, in <module>
    import zlib
ImportError: /opt/hpcc/CPU/anaconda/3-5.3.1/lib/python3.7/lib-dynload/zlib.cpython-37m-x86_64-linux-gnu.so: cannot open shared object file: Input/output error
Traceback (most recent call last):
  File "/opt/hpcc/CPU/anaconda/3-5.3.1/lib/python3.7/runpy.py", line 193, in _run_module_as_main
    "__main__", mod_spec)
  File "/opt/hpcc/CPU/anaconda/3-5.3.1/lib/python3.7/runpy.py", line 85, in _run_code
    exec(code, run_globals)
  File "/home/arlan.uy/.local/lib/python3.7/site-packages/pip/__main__.py", line 29, in <module>
    from pip._internal.cli.main import main as _main
  File "/home/arlan.uy/.local/lib/python3.7/site-packages/pip/_internal/cli/main.py", line 9, in <module>
    from pip._internal.cli.autocompletion import autocomplete
  File "/home/arlan.uy/.local/lib/python3.7/site-packages/pip/_internal/cli/autocompletion.py", line 10, in <module>
    from pip._internal.cli.main_parser import create_main_parser
  File "/home/arlan.uy/.local/lib/python3.7/site-packages/pip/_internal/cli/main_parser.py", line 8, in <module>
    from pip._internal.cli import cmdoptions
  File "/home/arlan.uy/.local/lib/python3.7/site-packages/pip/_internal/cli/cmdoptions.py", line 23, in <module>
    from pip._internal.cli.parser import ConfigOptionParser
  File "/home/arlan.uy/.local/lib/python3.7/site-packages/pip/_internal/cli/parser.py", line 12, in <module>
    from pip._internal.configuration import Configuration, ConfigurationError
  File "/home/arlan.uy/.local/lib/python3.7/site-packages/pip/_internal/configuration.py", line 21, in <module>
    from pip._internal.exceptions import (
  File "/home/arlan.uy/.local/lib/python3.7/site-packages/pip/_internal/exceptions.py", line 8, in <module>
    from pip._vendor.requests.models import Request, Response
  File "/home/arlan.uy/.local/lib/python3.7/site-packages/pip/_vendor/requests/__init__.py", line 43, in <module>
    from pip._vendor import urllib3
  File "/home/arlan.uy/.local/lib/python3.7/site-packages/pip/_vendor/urllib3/__init__.py", line 13, in <module>
    from .connectionpool import HTTPConnectionPool, HTTPSConnectionPool, connection_from_url
  File "/home/arlan.uy/.local/lib/python3.7/site-packages/pip/_vendor/urllib3/connectionpool.py", line 40, in <module>
    from .response import HTTPResponse
  File "/home/arlan.uy/.local/lib/python3.7/site-packages/pip/_vendor/urllib3/response.py", line 5, in <module>
    import zlib
ImportError: /opt/hpcc/CPU/anaconda/3-5.3.1/lib/python3.7/lib-dynload/zlib.cpython-37m-x86_64-linux-gnu.so: cannot open shared object file: Input/output error
Traceback (most recent call last):
  File "/opt/hpcc/CPU/anaconda/3-5.3.1/lib/python3.7/runpy.py", line 193, in _run_module_as_main
    "__main__", mod_spec)
  File "/opt/hpcc/CPU/anaconda/3-5.3.1/lib/python3.7/runpy.py", line 85, in _run_code
    exec(code, run_globals)
  File "/home/arlan.uy/.local/lib/python3.7/site-packages/pip/__main__.py", line 29, in <module>
    from pip._internal.cli.main import main as _main
  File "/home/arlan.uy/.local/lib/python3.7/site-packages/pip/_internal/cli/main.py", line 9, in <module>
    from pip._internal.cli.autocompletion import autocomplete
  File "/home/arlan.uy/.local/lib/python3.7/site-packages/pip/_internal/cli/autocompletion.py", line 10, in <module>
    from pip._internal.cli.main_parser import create_main_parser
  File "/home/arlan.uy/.local/lib/python3.7/site-packages/pip/_internal/cli/main_parser.py", line 8, in <module>
    from pip._internal.cli import cmdoptions
  File "/home/arlan.uy/.local/lib/python3.7/site-packages/pip/_internal/cli/cmdoptions.py", line 23, in <module>
    from pip._internal.cli.parser import ConfigOptionParser
  File "/home/arlan.uy/.local/lib/python3.7/site-packages/pip/_internal/cli/parser.py", line 12, in <module>
    from pip._internal.configuration import Configuration, ConfigurationError
  File "/home/arlan.uy/.local/lib/python3.7/site-packages/pip/_internal/configuration.py", line 21, in <module>
    from pip._internal.exceptions import (
  File "/home/arlan.uy/.local/lib/python3.7/site-packages/pip/_internal/exceptions.py", line 8, in <module>
    from pip._vendor.requests.models import Request, Response
  File "/home/arlan.uy/.local/lib/python3.7/site-packages/pip/_vendor/requests/__init__.py", line 43, in <module>
    from pip._vendor import urllib3
  File "/home/arlan.uy/.local/lib/python3.7/site-packages/pip/_vendor/urllib3/__init__.py", line 13, in <module>
    from .connectionpool import HTTPConnectionPool, HTTPSConnectionPool, connection_from_url
  File "/home/arlan.uy/.local/lib/python3.7/site-packages/pip/_vendor/urllib3/connectionpool.py", line 40, in <module>
    from .response import HTTPResponse
  File "/home/arlan.uy/.local/lib/python3.7/site-packages/pip/_vendor/urllib3/response.py", line 5, in <module>
    import zlib
ImportError: /opt/hpcc/CPU/anaconda/3-5.3.1/lib/python3.7/lib-dynload/zlib.cpython-37m-x86_64-linux-gnu.so: cannot open shared object file: Input/output error
srun: error: saliksik-gpu-05: tasks 0-5,7-11: Exited with exit code 1
Traceback (most recent call last):
  File "main.py", line 303, in <module>
    main()
  File "main.py", line 301, in main
    program_main(sys.argv)
  File "main.py", line 276, in program_main
    continue_create_empty_yaml(newloadfile_name)
  File "main.py", line 42, in continue_create_empty_yaml
    for i in range(run_start, ga_params['run_total'] + ga_params['runs_pending']):
KeyError: 'runs_pending'
Traceback (most recent call last):
  File "main.py", line 303, in <module>
    main()
  File "main.py", line 301, in main
    program_main(sys.argv)
  File "main.py", line 276, in program_main
    continue_create_empty_yaml(newloadfile_name)
  File "main.py", line 42, in continue_create_empty_yaml
    for i in range(run_start, ga_params['run_total'] + ga_params['runs_pending']):
KeyError: 'runs_pending'
Traceback (most recent call last):
  File "main.py", line 303, in <module>
    main()
  File "main.py", line 301, in main
    program_main(sys.argv)
  File "main.py", line 276, in program_main
    continue_create_empty_yaml(newloadfile_name)
  File "main.py", line 42, in continue_create_empty_yaml
    for i in range(run_start, ga_params['run_total'] + ga_params['runs_pending']):
KeyError: 'runs_pending'
Traceback (most recent call last):
  File "main.py", line 303, in <module>
    main()
  File "main.py", line 301, in main
    program_main(sys.argv)
  File "main.py", line 276, in program_main
    continue_create_empty_yaml(newloadfile_name)
  File "main.py", line 42, in continue_create_empty_yaml
    for i in range(run_start, ga_params['run_total'] + ga_params['runs_pending']):
KeyError: 'runs_pending'
srun: error: saliksik-gpu-05: tasks 1,4: Exited with exit code 1
Traceback (most recent call last):
  File "main.py", line 303, in <module>
    main()
  File "main.py", line 301, in main
    program_main(sys.argv)
  File "main.py", line 276, in program_main
    continue_create_empty_yaml(newloadfile_name)
  File "main.py", line 42, in continue_create_empty_yaml
    for i in range(run_start, ga_params['run_total'] + ga_params['runs_pending']):
KeyError: 'runs_pending'
Traceback (most recent call last):
  File "main.py", line 303, in <module>
    main()
  File "main.py", line 301, in main
    program_main(sys.argv)
  File "main.py", line 276, in program_main
    continue_create_empty_yaml(newloadfile_name)
  File "main.py", line 42, in continue_create_empty_yaml
    for i in range(run_start, ga_params['run_total'] + ga_params['runs_pending']):
KeyError: 'runs_pending'
srun: error: saliksik-gpu-05: task 7: Exited with exit code 1
srun: error: saliksik-gpu-05: tasks 10-11: Exited with exit code 1
Traceback (most recent call last):
  File "main.py", line 303, in <module>
    main()
  File "main.py", line 301, in main
    program_main(sys.argv)
  File "main.py", line 276, in program_main
    continue_create_empty_yaml(newloadfile_name)
  File "main.py", line 42, in continue_create_empty_yaml
    for i in range(run_start, ga_params['run_total'] + ga_params['runs_pending']):
KeyError: 'runs_pending'
srun: error: saliksik-gpu-05: task 6: Exited with exit code 1
srun: error: saliksik-gpu-05: task 3: Exited with exit code 1
Traceback (most recent call last):
  File "main.py", line 303, in <module>
    main()
  File "main.py", line 301, in main
    program_main(sys.argv)
  File "main.py", line 278, in program_main
    run_total = ga_params['run_total'] + ga_params['runs_pending']
KeyError: 'runs_pending'
srun: error: saliksik-gpu-05: task 0: Exited with exit code 1
Traceback (most recent call last):
  File "main.py", line 303, in <module>
    main()
  File "main.py", line 301, in main
    program_main(sys.argv)
  File "main.py", line 288, in program_main
    gaframework_gpu(newloadfile_name)
  File "/scratch1/scratch2/arlan.uy/ERSSNP_CPU_GPU_Framework/main_dir/src/experimenter_uncommented.py", line 34, in gaframework_gpu
    execute_experiment_gpu(ga, gaeval, ga_params, loadfile_name)
  File "/scratch1/scratch2/arlan.uy/ERSSNP_CPU_GPU_Framework/main_dir/src/experimenter_uncommented.py", line 63, in execute_experiment_gpu
    gaeval.run(ga, rssnp, stats_run['population_size'], stats_run['fitness_function'],  gaeval.no_of_run, gaeval.no_of_gen, stats_run['mutation_rate'], loadfile_name, stats_run['selection_func'], start_new, start_from_gen)
  File "/scratch1/scratch2/arlan.uy/ERSSNP_CPU_GPU_Framework/main_dir/src/abstracts/GAevaluator_integ.py", line 38, in run
    run_fitness = genetic_algo.simulate(system, size, function, generations, mutation_rate, path_name, run, selection_func, start_from_gen)            
  File "/scratch1/scratch2/arlan.uy/ERSSNP_CPU_GPU_Framework/main_dir/src/abstracts/geneticalgo_integ_gpu.py", line 438, in simulate
    self.evaluate(chrom, ga_params, fitness_func, selection_func)
  File "/scratch1/scratch2/arlan.uy/ERSSNP_CPU_GPU_Framework/main_dir/src/abstracts/geneticalgo_integ_gpu.py", line 382, in evaluate
    chromosome['fitness'] += int(self.assign_fitness(chromosome['out_pairs'][z][1], chromosome['out_pairs'][z][0], fitness_func, len_dataset)/minlen*100)
  File "/scratch1/scratch2/arlan.uy/ERSSNP_CPU_GPU_Framework/main_dir/src/abstracts/geneticalgo_integ_gpu.py", line 74, in assign_fitness
    result = GPUlcs(output_dataset, output_spike_train, len_dataset)
  File "/scratch1/scratch2/arlan.uy/ERSSNP_CPU_GPU_Framework/main_dir/src/abstracts/gpu_fitness.py", line 76, in GPUlcs
    timer_write("Evaluate", timer_gpu.time())
  File "/scratch1/scratch2/arlan.uy/ERSSNP_CPU_GPU_Framework/main_dir/src/abstracts/gpu_timer.py", line 30, in timer_write
    timer_params['run_indexes'][run_index_state][ga_name] += exec_time
TypeError: 'NoneType' object is not subscriptable
srun: error: saliksik-gpu-05: task 9: Exited with exit code 1
Traceback (most recent call last):
  File "main.py", line 303, in <module>
    main()
  File "main.py", line 301, in main
    program_main(sys.argv)
  File "main.py", line 288, in program_main
    gaframework_gpu(newloadfile_name)
  File "/scratch1/scratch2/arlan.uy/ERSSNP_CPU_GPU_Framework/main_dir/src/experimenter_uncommented.py", line 34, in gaframework_gpu
    execute_experiment_gpu(ga, gaeval, ga_params, loadfile_name)
  File "/scratch1/scratch2/arlan.uy/ERSSNP_CPU_GPU_Framework/main_dir/src/experimenter_uncommented.py", line 63, in execute_experiment_gpu
    gaeval.run(ga, rssnp, stats_run['population_size'], stats_run['fitness_function'],  gaeval.no_of_run, gaeval.no_of_gen, stats_run['mutation_rate'], loadfile_name, stats_run['selection_func'], start_new, start_from_gen)
  File "/scratch1/scratch2/arlan.uy/ERSSNP_CPU_GPU_Framework/main_dir/src/abstracts/GAevaluator_integ.py", line 38, in run
    run_fitness = genetic_algo.simulate(system, size, function, generations, mutation_rate, path_name, run, selection_func, start_from_gen)            
  File "/scratch1/scratch2/arlan.uy/ERSSNP_CPU_GPU_Framework/main_dir/src/abstracts/geneticalgo_integ_gpu.py", line 438, in simulate
    self.evaluate(chrom, ga_params, fitness_func, selection_func)
  File "/scratch1/scratch2/arlan.uy/ERSSNP_CPU_GPU_Framework/main_dir/src/abstracts/geneticalgo_integ_gpu.py", line 382, in evaluate
    chromosome['fitness'] += int(self.assign_fitness(chromosome['out_pairs'][z][1], chromosome['out_pairs'][z][0], fitness_func, len_dataset)/minlen*100)
  File "/scratch1/scratch2/arlan.uy/ERSSNP_CPU_GPU_Framework/main_dir/src/abstracts/geneticalgo_integ_gpu.py", line 74, in assign_fitness
    result = GPUlcs(output_dataset, output_spike_train, len_dataset)
  File "/scratch1/scratch2/arlan.uy/ERSSNP_CPU_GPU_Framework/main_dir/src/abstracts/gpu_fitness.py", line 76, in GPUlcs
    timer_write("Evaluate", timer_gpu.time())
  File "/scratch1/scratch2/arlan.uy/ERSSNP_CPU_GPU_Framework/main_dir/src/abstracts/gpu_timer.py", line 30, in timer_write
    timer_params['run_indexes'][run_index_state][ga_name] += exec_time
TypeError: 'NoneType' object is not subscriptable
srun: error: saliksik-gpu-05: task 2: Exited with exit code 1
Traceback (most recent call last):
  File "main.py", line 303, in <module>
    main()
  File "main.py", line 301, in main
    program_main(sys.argv)
  File "main.py", line 288, in program_main
    gaframework_gpu(newloadfile_name)
  File "/scratch1/scratch2/arlan.uy/ERSSNP_CPU_GPU_Framework/main_dir/src/experimenter_uncommented.py", line 34, in gaframework_gpu
    execute_experiment_gpu(ga, gaeval, ga_params, loadfile_name)
  File "/scratch1/scratch2/arlan.uy/ERSSNP_CPU_GPU_Framework/main_dir/src/experimenter_uncommented.py", line 63, in execute_experiment_gpu
    gaeval.run(ga, rssnp, stats_run['population_size'], stats_run['fitness_function'],  gaeval.no_of_run, gaeval.no_of_gen, stats_run['mutation_rate'], loadfile_name, stats_run['selection_func'], start_new, start_from_gen)
  File "/scratch1/scratch2/arlan.uy/ERSSNP_CPU_GPU_Framework/main_dir/src/abstracts/GAevaluator_integ.py", line 38, in run
    run_fitness = genetic_algo.simulate(system, size, function, generations, mutation_rate, path_name, run, selection_func, start_from_gen)            
  File "/scratch1/scratch2/arlan.uy/ERSSNP_CPU_GPU_Framework/main_dir/src/abstracts/geneticalgo_integ_gpu.py", line 438, in simulate
    self.evaluate(chrom, ga_params, fitness_func, selection_func)
  File "/scratch1/scratch2/arlan.uy/ERSSNP_CPU_GPU_Framework/main_dir/src/abstracts/geneticalgo_integ_gpu.py", line 382, in evaluate
    chromosome['fitness'] += int(self.assign_fitness(chromosome['out_pairs'][z][1], chromosome['out_pairs'][z][0], fitness_func, len_dataset)/minlen*100)
  File "/scratch1/scratch2/arlan.uy/ERSSNP_CPU_GPU_Framework/main_dir/src/abstracts/geneticalgo_integ_gpu.py", line 74, in assign_fitness
    result = GPUlcs(output_dataset, output_spike_train, len_dataset)
  File "/scratch1/scratch2/arlan.uy/ERSSNP_CPU_GPU_Framework/main_dir/src/abstracts/gpu_fitness.py", line 76, in GPUlcs
    timer_write("Evaluate", timer_gpu.time())
  File "/scratch1/scratch2/arlan.uy/ERSSNP_CPU_GPU_Framework/main_dir/src/abstracts/gpu_timer.py", line 30, in timer_write
    timer_params['run_indexes'][run_index_state][ga_name] += exec_time
TypeError: 'NoneType' object is not subscriptable
srun: error: saliksik-gpu-05: task 8: Exited with exit code 1
