>> anaconda-3-5.3.1 has been loaded.
>> python-3.8.2 has been loaded.
>> cuda-10.1_cudnn-7.6.5 has been loaded.
ERROR: Could not install packages due to an OSError: [Errno 2] No such file or directory: '/share/home/arlan.uy/.local/bin/pip'

ERROR: Could not install packages due to an OSError: [Errno 2] No such file or directory: '/share/home/arlan.uy/.local/bin/pip'

ERROR: Could not install packages due to an OSError: [Errno 2] No such file or directory: '/share/home/arlan.uy/.local/bin/pip'

ERROR: Could not install packages due to an OSError: [Errno 2] No such file or directory: '/share/home/arlan.uy/.local/bin/pip'

ERROR: Could not install packages due to an OSError: [Errno 2] No such file or directory: '/share/home/arlan.uy/.local/bin/pip'

ERROR: Could not install packages due to an OSError: [Errno 2] No such file or directory: '/share/home/arlan.uy/.local/bin/pip'

ERROR: Could not install packages due to an OSError: [Errno 2] No such file or directory: '/share/home/arlan.uy/.local/bin/pip'

ERROR: Could not install packages due to an OSError: [Errno 2] No such file or directory: '/share/home/arlan.uy/.local/bin/pip'

ERROR: Could not install packages due to an OSError: [Errno 2] No such file or directory: '/share/home/arlan.uy/.local/bin/pip'

ERROR: Could not install packages due to an OSError: [Errno 2] No such file or directory: '/share/home/arlan.uy/.local/bin/pip'

ERROR: Could not install packages due to an OSError: [Errno 2] No such file or directory: '/share/home/arlan.uy/.local/bin/pip'

srun: error: saliksik-gpu-05: tasks 0-8,10-11: Exited with exit code 1
Traceback (most recent call last):
  File "main.py", line 303, in <module>
    main()
  File "main.py", line 301, in main
    program_main(sys.argv)
  File "main.py", line 276, in program_main
    continue_create_empty_yaml(newloadfile_name)
  File "main.py", line 39, in continue_create_empty_yaml
    ga_params = conf_load(savefile_name)
  File "main.py", line 15, in conf_load
    return ga_params
UnboundLocalError: local variable 'ga_params' referenced before assignment
Traceback (most recent call last):
  File "main.py", line 303, in <module>
    main()
  File "main.py", line 301, in main
    program_main(sys.argv)
  File "main.py", line 276, in program_main
    continue_create_empty_yaml(newloadfile_name)
  File "main.py", line 39, in continue_create_empty_yaml
    ga_params = conf_load(savefile_name)
  File "main.py", line 15, in conf_load
    return ga_params
UnboundLocalError: local variable 'ga_params' referenced before assignment
Traceback (most recent call last):
  File "main.py", line 303, in <module>
    main()
  File "main.py", line 301, in main
    program_main(sys.argv)
  File "main.py", line 276, in program_main
    continue_create_empty_yaml(newloadfile_name)
  File "main.py", line 39, in continue_create_empty_yaml
    ga_params = conf_load(savefile_name)
  File "main.py", line 15, in conf_load
    return ga_params
UnboundLocalError: local variable 'ga_params' referenced before assignment
srun: error: saliksik-gpu-05: task 10: Exited with exit code 1
srun: error: saliksik-gpu-05: tasks 1,3: Exited with exit code 1
Traceback (most recent call last):
  File "main.py", line 303, in <module>
    main()
  File "main.py", line 301, in main
    program_main(sys.argv)
  File "main.py", line 276, in program_main
    continue_create_empty_yaml(newloadfile_name)
  File "main.py", line 42, in continue_create_empty_yaml
    for i in range(run_start, ga_params['run_total'] + ga_params['runs_pending']):
KeyError: 'runs_pending'
Traceback (most recent call last):
  File "main.py", line 303, in <module>
    main()
  File "main.py", line 301, in main
    program_main(sys.argv)
  File "main.py", line 276, in program_main
    continue_create_empty_yaml(newloadfile_name)
  File "main.py", line 42, in continue_create_empty_yaml
    for i in range(run_start, ga_params['run_total'] + ga_params['runs_pending']):
KeyError: 'runs_pending'
Traceback (most recent call last):
  File "main.py", line 303, in <module>
    main()
  File "main.py", line 301, in main
    program_main(sys.argv)
  File "main.py", line 276, in program_main
    continue_create_empty_yaml(newloadfile_name)
  File "main.py", line 42, in continue_create_empty_yaml
    for i in range(run_start, ga_params['run_total'] + ga_params['runs_pending']):
KeyError: 'runs_pending'
Traceback (most recent call last):
  File "main.py", line 303, in <module>
    main()
  File "main.py", line 301, in main
    program_main(sys.argv)
  File "main.py", line 276, in program_main
    continue_create_empty_yaml(newloadfile_name)
  File "main.py", line 42, in continue_create_empty_yaml
    for i in range(run_start, ga_params['run_total'] + ga_params['runs_pending']):
KeyError: 'runs_pending'
srun: error: saliksik-gpu-05: tasks 0,6: Exited with exit code 1
Traceback (most recent call last):
  File "main.py", line 303, in <module>
    main()
  File "main.py", line 301, in main
    program_main(sys.argv)
  File "main.py", line 276, in program_main
    continue_create_empty_yaml(newloadfile_name)
  File "main.py", line 42, in continue_create_empty_yaml
    for i in range(run_start, ga_params['run_total'] + ga_params['runs_pending']):
KeyError: 'runs_pending'
Traceback (most recent call last):
  File "main.py", line 303, in <module>
    main()
  File "main.py", line 301, in main
    program_main(sys.argv)
  File "main.py", line 276, in program_main
    continue_create_empty_yaml(newloadfile_name)
  File "main.py", line 42, in continue_create_empty_yaml
    for i in range(run_start, ga_params['run_total'] + ga_params['runs_pending']):
KeyError: 'runs_pending'
Traceback (most recent call last):
  File "main.py", line 303, in <module>
    main()
  File "main.py", line 301, in main
    program_main(sys.argv)
  File "main.py", line 276, in program_main
    continue_create_empty_yaml(newloadfile_name)
  File "main.py", line 42, in continue_create_empty_yaml
    for i in range(run_start, ga_params['run_total'] + ga_params['runs_pending']):
KeyError: 'runs_pending'
srun: error: saliksik-gpu-05: tasks 2,11: Exited with exit code 1
srun: error: saliksik-gpu-05: tasks 5,7-8: Exited with exit code 1
Traceback (most recent call last):
  File "main.py", line 303, in <module>
    main()
  File "main.py", line 301, in main
    program_main(sys.argv)
  File "main.py", line 288, in program_main
    gaframework_gpu(newloadfile_name)
  File "/scratch1/scratch2/arlan.uy/ERSSNP_CPU_GPU_Framework/main_dir/src/experimenter_uncommented.py", line 34, in gaframework_gpu
    execute_experiment_gpu(ga, gaeval, ga_params, loadfile_name)
  File "/scratch1/scratch2/arlan.uy/ERSSNP_CPU_GPU_Framework/main_dir/src/experimenter_uncommented.py", line 63, in execute_experiment_gpu
    gaeval.run(ga, rssnp, stats_run['population_size'], stats_run['fitness_function'],  gaeval.no_of_run, gaeval.no_of_gen, stats_run['mutation_rate'], loadfile_name, stats_run['selection_func'], start_new, start_from_gen)
  File "/scratch1/scratch2/arlan.uy/ERSSNP_CPU_GPU_Framework/main_dir/src/abstracts/GAevaluator_integ.py", line 38, in run
    run_fitness = genetic_algo.simulate(system, size, function, generations, mutation_rate, path_name, run, selection_func, start_from_gen)            
  File "/scratch1/scratch2/arlan.uy/ERSSNP_CPU_GPU_Framework/main_dir/src/abstracts/geneticalgo_integ_gpu.py", line 438, in simulate
    self.evaluate(chrom, ga_params, fitness_func, selection_func)
  File "/scratch1/scratch2/arlan.uy/ERSSNP_CPU_GPU_Framework/main_dir/src/abstracts/geneticalgo_integ_gpu.py", line 382, in evaluate
    chromosome['fitness'] += int(self.assign_fitness(chromosome['out_pairs'][z][1], chromosome['out_pairs'][z][0], fitness_func, len_dataset)/minlen*100)
  File "/scratch1/scratch2/arlan.uy/ERSSNP_CPU_GPU_Framework/main_dir/src/abstracts/geneticalgo_integ_gpu.py", line 74, in assign_fitness
    result = GPUlcs(output_dataset, output_spike_train, len_dataset)
  File "/scratch1/scratch2/arlan.uy/ERSSNP_CPU_GPU_Framework/main_dir/src/abstracts/gpu_fitness.py", line 76, in GPUlcs
    timer_write("Evaluate", timer_gpu.time())
  File "/scratch1/scratch2/arlan.uy/ERSSNP_CPU_GPU_Framework/main_dir/src/abstracts/gpu_timer.py", line 30, in timer_write
    timer_params['run_indexes'][run_index_state][ga_name] += exec_time
TypeError: 'NoneType' object is not subscriptable
srun: error: saliksik-gpu-05: task 9: Exited with exit code 1
slurmstepd: error: _is_a_lwp: open() /proc/14687/status failed: No such file or directory
Traceback (most recent call last):
  File "/home/arlan.uy/.local/lib/python3.7/site-packages/pytools/prefork.py", line 49, in call_capture_output
  File "/opt/hpcc/CPU/anaconda/3-5.3.1/lib/python3.7/subprocess.py", line 756, in __init__
  File "/opt/hpcc/CPU/anaconda/3-5.3.1/lib/python3.7/subprocess.py", line 1499, in _execute_child
PermissionError: [Errno 13] Permission denied: 'nvcc'

During handling of the above exception, another exception occurred:

Traceback (most recent call last):
  File "main.py", line 303, in <module>
    main()
  File "main.py", line 301, in main
    program_main(sys.argv)
  File "main.py", line 288, in program_main
    gaframework_gpu(newloadfile_name)
  File "/scratch1/scratch2/arlan.uy/ERSSNP_CPU_GPU_Framework/main_dir/src/experimenter_uncommented.py", line 34, in gaframework_gpu
    execute_experiment_gpu(ga, gaeval, ga_params, loadfile_name)
  File "/scratch1/scratch2/arlan.uy/ERSSNP_CPU_GPU_Framework/main_dir/src/experimenter_uncommented.py", line 63, in execute_experiment_gpu
    gaeval.run(ga, rssnp, stats_run['population_size'], stats_run['fitness_function'],  gaeval.no_of_run, gaeval.no_of_gen, stats_run['mutation_rate'], loadfile_name, stats_run['selection_func'], start_new, start_from_gen)
  File "/scratch1/scratch2/arlan.uy/ERSSNP_CPU_GPU_Framework/main_dir/src/abstracts/GAevaluator_integ.py", line 38, in run
    run_fitness = genetic_algo.simulate(system, size, function, generations, mutation_rate, path_name, run, selection_func, start_from_gen)            
  File "/scratch1/scratch2/arlan.uy/ERSSNP_CPU_GPU_Framework/main_dir/src/abstracts/geneticalgo_integ_gpu.py", line 438, in simulate
    self.evaluate(chrom, ga_params, fitness_func, selection_func)
  File "/scratch1/scratch2/arlan.uy/ERSSNP_CPU_GPU_Framework/main_dir/src/abstracts/geneticalgo_integ_gpu.py", line 382, in evaluate
    chromosome['fitness'] += int(self.assign_fitness(chromosome['out_pairs'][z][1], chromosome['out_pairs'][z][0], fitness_func, len_dataset)/minlen*100)
  File "/scratch1/scratch2/arlan.uy/ERSSNP_CPU_GPU_Framework/main_dir/src/abstracts/geneticalgo_integ_gpu.py", line 74, in assign_fitness
    result = GPUlcs(output_dataset, output_spike_train, len_dataset)
  File "/scratch1/scratch2/arlan.uy/ERSSNP_CPU_GPU_Framework/main_dir/src/abstracts/gpu_fitness.py", line 49, in GPUlcs
    """)
  File "/home/arlan.uy/.local/lib/python3.7/site-packages/pycuda/compiler.py", line 291, in __init__
  File "/home/arlan.uy/.local/lib/python3.7/site-packages/pycuda/compiler.py", line 254, in compile
  File "/home/arlan.uy/.local/lib/python3.7/site-packages/pycuda/compiler.py", line 78, in compile_plain
  File "/home/arlan.uy/.local/lib/python3.7/site-packages/pycuda/compiler.py", line 50, in preprocess_source
  File "/home/arlan.uy/.local/lib/python3.7/site-packages/pytools/prefork.py", line 226, in call_capture_output
  File "/home/arlan.uy/.local/lib/python3.7/site-packages/pytools/prefork.py", line 60, in call_capture_output
pytools.prefork.ExecError: error invoking 'nvcc --preprocess -arch sm_61 -I/share/home/arlan.uy/.local/lib/python3.7/site-packages/pycuda/cuda /tmp/tmp7fv7yl6z.cu --compiler-options -P': [Errno 13] Permission denied: 'nvcc'
srun: error: saliksik-gpu-05: task 4: Exited with exit code 1
