>> anaconda-3-5.3.1 has been loaded.
>> python-3.8.2 has been loaded.
>> cuda-10.1_cudnn-7.6.5 has been loaded.
WARNING: Value for scheme.headers does not match. Please report this to <https://github.com/pypa/pip/issues/10151>
distutils: /home/arlan.uy/.local/include/python3.7m/UNKNOWN
sysconfig: /home/arlan.uy/.local/include/python3.7/UNKNOWN
WARNING: Additional context:
user = True
home = None
root = None
prefix = None
WARNING: Value for scheme.headers does not match. Please report this to <https://github.com/pypa/pip/issues/10151>
distutils: /home/arlan.uy/.local/include/python3.7m/UNKNOWN
sysconfig: /home/arlan.uy/.local/include/python3.7/UNKNOWN
WARNING: Additional context:
user = True
home = None
root = None
prefix = None
WARNING: Value for scheme.headers does not match. Please report this to <https://github.com/pypa/pip/issues/10151>
distutils: /home/arlan.uy/.local/include/python3.7m/UNKNOWN
sysconfig: /home/arlan.uy/.local/include/python3.7/UNKNOWN
WARNING: Additional context:
user = True
home = None
root = None
prefix = None
WARNING: Value for scheme.headers does not match. Please report this to <https://github.com/pypa/pip/issues/10151>
distutils: /home/arlan.uy/.local/include/python3.7m/UNKNOWN
sysconfig: /home/arlan.uy/.local/include/python3.7/UNKNOWN
WARNING: Additional context:
user = True
home = None
root = None
prefix = None
WARNING: Value for scheme.headers does not match. Please report this to <https://github.com/pypa/pip/issues/10151>
distutils: /home/arlan.uy/.local/include/python3.7m/UNKNOWN
sysconfig: /home/arlan.uy/.local/include/python3.7/UNKNOWN
WARNING: Additional context:
user = True
home = None
root = None
prefix = None
WARNING: Value for scheme.headers does not match. Please report this to <https://github.com/pypa/pip/issues/10151>
distutils: /home/arlan.uy/.local/include/python3.7m/UNKNOWN
sysconfig: /home/arlan.uy/.local/include/python3.7/UNKNOWN
WARNING: Additional context:
user = True
home = None
root = None
prefix = None
WARNING: Value for scheme.headers does not match. Please report this to <https://github.com/pypa/pip/issues/10151>
distutils: /home/arlan.uy/.local/include/python3.7m/UNKNOWN
sysconfig: /home/arlan.uy/.local/include/python3.7/UNKNOWN
WARNING: Additional context:
user = True
home = None
root = None
prefix = None
WARNING: Value for scheme.headers does not match. Please report this to <https://github.com/pypa/pip/issues/10151>
distutils: /home/arlan.uy/.local/include/python3.7m/UNKNOWN
sysconfig: /home/arlan.uy/.local/include/python3.7/UNKNOWN
WARNING: Value for scheme.headers does not match. Please report this to <https://github.com/pypa/pip/issues/10151>
distutils: /home/arlan.uy/.local/include/python3.7m/UNKNOWN
sysconfig: /home/arlan.uy/.local/include/python3.7/UNKNOWN
WARNING: Value for scheme.headers does not match. Please report this to <https://github.com/pypa/pip/issues/10151>
distutils: /home/arlan.uy/.local/include/python3.7m/UNKNOWN
sysconfig: /home/arlan.uy/.local/include/python3.7/UNKNOWN
WARNING: Additional context:
user = True
home = None
root = None
prefix = None
WARNING: Additional context:
user = True
home = None
root = None
prefix = None
WARNING: Additional context:
user = True
home = None
root = None
prefix = None
WARNING: Value for scheme.headers does not match. Please report this to <https://github.com/pypa/pip/issues/10151>
distutils: /home/arlan.uy/.local/include/python3.7m/UNKNOWN
sysconfig: /home/arlan.uy/.local/include/python3.7/UNKNOWN
WARNING: Value for scheme.headers does not match. Please report this to <https://github.com/pypa/pip/issues/10151>
distutils: /home/arlan.uy/.local/include/python3.7m/UNKNOWN
sysconfig: /home/arlan.uy/.local/include/python3.7/UNKNOWN
WARNING: Additional context:
user = True
home = None
root = None
prefix = None
WARNING: Additional context:
user = True
home = None
root = None
prefix = None
Traceback (most recent call last):
  File "/opt/hpcc/CPU/anaconda/3-5.3.1/lib/python3.7/runpy.py", line 193, in _run_module_as_main
    "__main__", mod_spec)
  File "/opt/hpcc/CPU/anaconda/3-5.3.1/lib/python3.7/runpy.py", line 85, in _run_code
    exec(code, run_globals)
  File "/home/arlan.uy/.local/lib/python3.7/site-packages/pip/__main__.py", line 29, in <module>
    from pip._internal.cli.main import main as _main
  File "/home/arlan.uy/.local/lib/python3.7/site-packages/pip/_internal/cli/main.py", line 9, in <module>
    from pip._internal.cli.autocompletion import autocomplete
  File "/home/arlan.uy/.local/lib/python3.7/site-packages/pip/_internal/cli/autocompletion.py", line 10, in <module>
    from pip._internal.cli.main_parser import create_main_parser
  File "/home/arlan.uy/.local/lib/python3.7/site-packages/pip/_internal/cli/main_parser.py", line 8, in <module>
    from pip._internal.cli import cmdoptions
  File "/home/arlan.uy/.local/lib/python3.7/site-packages/pip/_internal/cli/cmdoptions.py", line 23, in <module>
    from pip._internal.cli.parser import ConfigOptionParser
  File "/home/arlan.uy/.local/lib/python3.7/site-packages/pip/_internal/cli/parser.py", line 12, in <module>
    from pip._internal.configuration import Configuration, ConfigurationError
  File "/home/arlan.uy/.local/lib/python3.7/site-packages/pip/_internal/configuration.py", line 21, in <module>
    from pip._internal.exceptions import (
  File "/home/arlan.uy/.local/lib/python3.7/site-packages/pip/_internal/exceptions.py", line 7, in <module>
    from pip._vendor.pkg_resources import Distribution
  File "/home/arlan.uy/.local/lib/python3.7/site-packages/pip/_vendor/pkg_resources/__init__.py", line 3251, in <module>
    @_call_aside
  File "/home/arlan.uy/.local/lib/python3.7/site-packages/pip/_vendor/pkg_resources/__init__.py", line 3235, in _call_aside
    f(*args, **kwargs)
  File "/home/arlan.uy/.local/lib/python3.7/site-packages/pip/_vendor/pkg_resources/__init__.py", line 3264, in _initialize_master_working_set
    working_set = WorkingSet._build_master()
  File "/home/arlan.uy/.local/lib/python3.7/site-packages/pip/_vendor/pkg_resources/__init__.py", line 574, in _build_master
    ws = cls()
  File "/home/arlan.uy/.local/lib/python3.7/site-packages/pip/_vendor/pkg_resources/__init__.py", line 567, in __init__
    self.add_entry(entry)
  File "/home/arlan.uy/.local/lib/python3.7/site-packages/pip/_vendor/pkg_resources/__init__.py", line 623, in add_entry
    for dist in find_distributions(entry, True):
  File "/home/arlan.uy/.local/lib/python3.7/site-packages/pip/_vendor/pkg_resources/__init__.py", line 2065, in find_on_path
    for dist in factory(fullpath):
  File "/home/arlan.uy/.local/lib/python3.7/site-packages/pip/_vendor/pkg_resources/__init__.py", line 2135, in distributions_from_metadata
    root, entry, metadata, precedence=DEVELOP_DIST,
  File "/home/arlan.uy/.local/lib/python3.7/site-packages/pip/_vendor/pkg_resources/__init__.py", line 2592, in from_location
    py_version=py_version, platform=platform, **kw
  File "/home/arlan.uy/.local/lib/python3.7/site-packages/pip/_vendor/pkg_resources/__init__.py", line 2994, in _reload_version
    md_version = self._get_version()
  File "/home/arlan.uy/.local/lib/python3.7/site-packages/pip/_vendor/pkg_resources/__init__.py", line 2772, in _get_version
    version = _version_from_file(lines)
  File "/home/arlan.uy/.local/lib/python3.7/site-packages/pip/_vendor/pkg_resources/__init__.py", line 2556, in _version_from_file
    line = next(iter(version_lines), '')
  File "/home/arlan.uy/.local/lib/python3.7/site-packages/pip/_vendor/pkg_resources/__init__.py", line 2767, in _get_metadata
    for line in self.get_metadata_lines(name):
  File "/home/arlan.uy/.local/lib/python3.7/site-packages/pip/_vendor/pkg_resources/__init__.py", line 1911, in get_metadata_lines
    return yield_lines(self.get_metadata(name))
  File "/home/arlan.uy/.local/lib/python3.7/site-packages/pip/_vendor/pkg_resources/__init__.py", line 1897, in get_metadata
    with io.open(self.path, encoding='utf-8', errors="replace") as f:
OSError: [Errno 5] Input/output error: '/share/hpcc/CPU/anaconda/3-5.3.1/lib/python3.7/site-packages/locket-0.2.0-py3.7.egg-info'
srun: error: saliksik-gpu-06: task 8: Exited with exit code 1
WARNING: Value for scheme.headers does not match. Please report this to <https://github.com/pypa/pip/issues/10151>
distutils: /home/arlan.uy/.local/include/python3.7m/UNKNOWN
sysconfig: /home/arlan.uy/.local/include/python3.7/UNKNOWN
WARNING: Value for scheme.headers does not match. Please report this to <https://github.com/pypa/pip/issues/10151>
distutils: /home/arlan.uy/.local/include/python3.7m/UNKNOWN
sysconfig: /home/arlan.uy/.local/include/python3.7/UNKNOWN
WARNING: Additional context:
user = True
home = None
root = None
prefix = None
WARNING: Additional context:
user = True
home = None
root = None
prefix = None
WARNING: Value for scheme.headers does not match. Please report this to <https://github.com/pypa/pip/issues/10151>
distutils: /home/arlan.uy/.local/include/python3.7m/UNKNOWN
sysconfig: /home/arlan.uy/.local/include/python3.7/UNKNOWN
WARNING: Additional context:
user = True
home = None
root = None
prefix = None
WARNING: Value for scheme.headers does not match. Please report this to <https://github.com/pypa/pip/issues/10151>
distutils: /home/arlan.uy/.local/include/python3.7m/UNKNOWN
sysconfig: /home/arlan.uy/.local/include/python3.7/UNKNOWN
WARNING: Additional context:
user = True
home = None
root = None
prefix = None
WARNING: Value for scheme.headers does not match. Please report this to <https://github.com/pypa/pip/issues/10151>
distutils: /home/arlan.uy/.local/include/python3.7m/UNKNOWN
sysconfig: /home/arlan.uy/.local/include/python3.7/UNKNOWN
WARNING: Additional context:
user = True
home = None
root = None
prefix = None
WARNING: Value for scheme.headers does not match. Please report this to <https://github.com/pypa/pip/issues/10151>
distutils: /home/arlan.uy/.local/include/python3.7m/UNKNOWN
sysconfig: /home/arlan.uy/.local/include/python3.7/UNKNOWN
WARNING: Additional context:
user = True
home = None
root = None
prefix = None
WARNING: Value for scheme.headers does not match. Please report this to <https://github.com/pypa/pip/issues/10151>
distutils: /home/arlan.uy/.local/include/python3.7m/UNKNOWN
sysconfig: /home/arlan.uy/.local/include/python3.7/UNKNOWN
WARNING: Additional context:
user = True
home = None
root = None
prefix = None
WARNING: Value for scheme.headers does not match. Please report this to <https://github.com/pypa/pip/issues/10151>
distutils: /home/arlan.uy/.local/include/python3.7m/UNKNOWN
sysconfig: /home/arlan.uy/.local/include/python3.7/UNKNOWN
WARNING: Value for scheme.headers does not match. Please report this to <https://github.com/pypa/pip/issues/10151>
distutils: /home/arlan.uy/.local/include/python3.7m/UNKNOWN
sysconfig: /home/arlan.uy/.local/include/python3.7/UNKNOWN
WARNING: Additional context:
user = True
home = None
root = None
prefix = None
WARNING: Additional context:
user = True
home = None
root = None
prefix = None
WARNING: Value for scheme.headers does not match. Please report this to <https://github.com/pypa/pip/issues/10151>
distutils: /home/arlan.uy/.local/include/python3.7m/UNKNOWN
sysconfig: /home/arlan.uy/.local/include/python3.7/UNKNOWN
WARNING: Additional context:
user = True
home = None
root = None
prefix = None
WARNING: Value for scheme.headers does not match. Please report this to <https://github.com/pypa/pip/issues/10151>
distutils: /home/arlan.uy/.local/include/python3.7m/UNKNOWN
sysconfig: /home/arlan.uy/.local/include/python3.7/UNKNOWN
WARNING: Additional context:
user = True
home = None
root = None
prefix = None
Traceback (most recent call last):
  File "main.py", line 303, in <module>
    main()
  File "main.py", line 301, in main
    program_main(sys.argv)
  File "main.py", line 276, in program_main
    continue_create_empty_yaml(newloadfile_name)
  File "main.py", line 39, in continue_create_empty_yaml
    ga_params = conf_load(savefile_name)
  File "main.py", line 15, in conf_load
    return ga_params
UnboundLocalError: local variable 'ga_params' referenced before assignment
srun: error: saliksik-gpu-06: task 11: Exited with exit code 1
Traceback (most recent call last):
  File "main.py", line 303, in <module>
    main()
  File "main.py", line 301, in main
    program_main(sys.argv)
  File "main.py", line 276, in program_main
    continue_create_empty_yaml(newloadfile_name)
  File "main.py", line 42, in continue_create_empty_yaml
    for i in range(run_start, ga_params['run_total'] + ga_params['runs_pending']):
KeyError: 'runs_pending'
srun: error: saliksik-gpu-06: task 10: Exited with exit code 1
Traceback (most recent call last):
  File "main.py", line 303, in <module>
    main()
  File "main.py", line 301, in main
    program_main(sys.argv)
  File "main.py", line 276, in program_main
    continue_create_empty_yaml(newloadfile_name)
  File "main.py", line 42, in continue_create_empty_yaml
    for i in range(run_start, ga_params['run_total'] + ga_params['runs_pending']):
KeyError: 'runs_pending'
Traceback (most recent call last):
  File "main.py", line 303, in <module>
    main()
  File "main.py", line 301, in main
    program_main(sys.argv)
  File "main.py", line 276, in program_main
    continue_create_empty_yaml(newloadfile_name)
  File "main.py", line 42, in continue_create_empty_yaml
    for i in range(run_start, ga_params['run_total'] + ga_params['runs_pending']):
KeyError: 'runs_pending'
Traceback (most recent call last):
  File "main.py", line 303, in <module>
    main()
  File "main.py", line 301, in main
    program_main(sys.argv)
  File "main.py", line 276, in program_main
    continue_create_empty_yaml(newloadfile_name)
  File "main.py", line 42, in continue_create_empty_yaml
    for i in range(run_start, ga_params['run_total'] + ga_params['runs_pending']):
KeyError: 'runs_pending'
srun: error: saliksik-gpu-06: tasks 6,8-9: Exited with exit code 1
Traceback (most recent call last):
  File "main.py", line 303, in <module>
    main()
  File "main.py", line 301, in main
    program_main(sys.argv)
  File "main.py", line 278, in program_main
    run_total = ga_params['run_total'] + ga_params['runs_pending']
KeyError: 'runs_pending'
Traceback (most recent call last):
  File "main.py", line 303, in <module>
    main()
  File "main.py", line 301, in main
    program_main(sys.argv)
  File "main.py", line 278, in program_main
    run_total = ga_params['run_total'] + ga_params['runs_pending']
KeyError: 'runs_pending'
srun: error: saliksik-gpu-06: tasks 4-5: Exited with exit code 1
Traceback (most recent call last):
  File "main.py", line 303, in <module>
    main()
  File "main.py", line 301, in main
    program_main(sys.argv)
  File "main.py", line 278, in program_main
    run_total = ga_params['run_total'] + ga_params['runs_pending']
KeyError: 'runs_pending'
Traceback (most recent call last):
  File "main.py", line 303, in <module>
    main()
  File "main.py", line 301, in main
    program_main(sys.argv)
  File "main.py", line 278, in program_main
    run_total = ga_params['run_total'] + ga_params['runs_pending']
KeyError: 'runs_pending'
Traceback (most recent call last):
  File "main.py", line 303, in <module>
    main()
  File "main.py", line 301, in main
    program_main(sys.argv)
  File "main.py", line 278, in program_main
    run_total = ga_params['run_total'] + ga_params['runs_pending']
KeyError: 'runs_pending'
Traceback (most recent call last):
  File "main.py", line 303, in <module>
    main()
  File "main.py", line 301, in main
    program_main(sys.argv)
  File "main.py", line 278, in program_main
    run_total = ga_params['run_total'] + ga_params['runs_pending']
KeyError: 'runs_pending'
srun: error: saliksik-gpu-06: tasks 0-3: Exited with exit code 1
srun: Job step aborted: Waiting up to 32 seconds for job step to finish.
slurmstepd: error: *** JOB 238904 ON saliksik-gpu-06 CANCELLED AT 2021-07-27T18:51:07 ***
slurmstepd: error: *** STEP 238904.2 ON saliksik-gpu-06 CANCELLED AT 2021-07-27T18:51:07 ***
