>> anaconda-3-5.3.1 has been loaded.
>> python-3.8.2 has been loaded.
>> cuda-10.1_cudnn-7.6.5 has been loaded.
Traceback (most recent call last):
  File "main.py", line 299, in <module>
    main()
  File "main.py", line 297, in main
    program_main(sys.argc, sys.argv)
AttributeError: module 'sys' has no attribute 'argc'
Traceback (most recent call last):
  File "main.py", line 299, in <module>
    main()
  File "main.py", line 297, in main
    program_main(sys.argc, sys.argv)
AttributeError: module 'sys' has no attribute 'argc'
Traceback (most recent call last):
  File "main.py", line 299, in <module>
    main()
  File "main.py", line 297, in main
    program_main(sys.argc, sys.argv)
AttributeError: module 'sys' has no attribute 'argc'
Traceback (most recent call last):
  File "main.py", line 299, in <module>
    main()
  File "main.py", line 297, in main
    program_main(sys.argc, sys.argv)
AttributeError: module 'sys' has no attribute 'argc'
Traceback (most recent call last):
  File "main.py", line 299, in <module>
    main()
  File "main.py", line 297, in main
    program_main(sys.argc, sys.argv)
AttributeError: module 'sys' has no attribute 'argc'
Traceback (most recent call last):
  File "main.py", line 299, in <module>
    main()
  File "main.py", line 297, in main
    program_main(sys.argc, sys.argv)
AttributeError: module 'sys' has no attribute 'argc'
Traceback (most recent call last):
  File "main.py", line 299, in <module>
    main()
  File "main.py", line 297, in main
    program_main(sys.argc, sys.argv)
AttributeError: module 'sys' has no attribute 'argc'
Traceback (most recent call last):
  File "main.py", line 299, in <module>
    main()
  File "main.py", line 297, in main
    program_main(sys.argc, sys.argv)
AttributeError: module 'sys' has no attribute 'argc'
srun: error: saliksik-gpu-06: tasks 0-3,5-7: Exited with exit code 1
srun: error: saliksik-gpu-06: task 4: Exited with exit code 1
