>> anaconda-3-5.3.1 has been loaded.
>> python-3.8.2 has been loaded.
>> cuda-10.1_cudnn-7.6.5 has been loaded.
Could not install packages due to an EnvironmentError: [Errno 5] Input/output error: '/share/hpcc/CPU/anaconda/3-5.3.1/lib/python3.7/site-packages/numexpr-2.6.8-py3.7.egg-info/requires.txt'

Could not install packages due to an EnvironmentError: [Errno 5] Input/output error: '/share/hpcc/CPU/anaconda/3-5.3.1/lib/python3.7/site-packages/numexpr-2.6.8-py3.7.egg-info/requires.txt'

Could not install packages due to an EnvironmentError: [Errno 5] Input/output error

Could not install packages due to an EnvironmentError: [Errno 5] Input/output error: '/share/hpcc/CPU/anaconda/3-5.3.1/lib/python3.7/site-packages/numexpr-2.6.8-py3.7.egg-info/requires.txt'

Could not install packages due to an EnvironmentError: [Errno 2] No such file or directory: '/home/arlan.uy/.local/lib/python3.7/site-packages/pip/__init__.py'

You are using pip version 10.0.1, however version 21.1.3 is available.
You should consider upgrading via the 'pip install --upgrade pip' command.
You are using pip version 10.0.1, however version 21.1.3 is available.
You should consider upgrading via the 'pip install --upgrade pip' command.
You are using pip version 10.0.1, however version 21.1.3 is available.
You should consider upgrading via the 'pip install --upgrade pip' command.
You are using pip version 10.0.1, however version 21.1.3 is available.
You should consider upgrading via the 'pip install --upgrade pip' command.
srun: error: saliksik-cpu-21: tasks 0-2,4: Exited with exit code 1
Could not install packages due to an EnvironmentError: [Errno 2] No such file or directory: '/home/arlan.uy/.local/lib/python3.7/site-packages/pip/_internal/metadata/__init__.py'

You are using pip version 10.0.1, however version 21.1.3 is available.
You should consider upgrading via the 'pip install --upgrade pip' command.
srun: error: saliksik-cpu-21: task 6: Exited with exit code 1
srun: error: saliksik-cpu-21: task 7: Exited with exit code 1
Traceback (most recent call last):
  File "/opt/hpcc/CPU/anaconda/3-5.3.1/lib/python3.7/runpy.py", line 193, in _run_module_as_main
    "__main__", mod_spec)
  File "/opt/hpcc/CPU/anaconda/3-5.3.1/lib/python3.7/runpy.py", line 85, in _run_code
    exec(code, run_globals)
  File "/home/arlan.uy/.local/lib/python3.7/site-packages/pip/__main__.py", line 29, in <module>
    from pip._internal.cli.main import main as _main
  File "/home/arlan.uy/.local/lib/python3.7/site-packages/pip/_internal/cli/main.py", line 9, in <module>
    from pip._internal.cli.autocompletion import autocomplete
  File "/home/arlan.uy/.local/lib/python3.7/site-packages/pip/_internal/cli/autocompletion.py", line 10, in <module>
    from pip._internal.cli.main_parser import create_main_parser
  File "/home/arlan.uy/.local/lib/python3.7/site-packages/pip/_internal/cli/main_parser.py", line 8, in <module>
    from pip._internal.cli import cmdoptions
  File "/home/arlan.uy/.local/lib/python3.7/site-packages/pip/_internal/cli/cmdoptions.py", line 23, in <module>
    from pip._internal.cli.parser import ConfigOptionParser
  File "/home/arlan.uy/.local/lib/python3.7/site-packages/pip/_internal/cli/parser.py", line 12, in <module>
    from pip._internal.configuration import Configuration, ConfigurationError
  File "/home/arlan.uy/.local/lib/python3.7/site-packages/pip/_internal/configuration.py", line 21, in <module>
    from pip._internal.exceptions import (
  File "/home/arlan.uy/.local/lib/python3.7/site-packages/pip/_internal/exceptions.py", line 7, in <module>
    from pip._vendor.pkg_resources import Distribution
  File "/home/arlan.uy/.local/lib/python3.7/site-packages/pip/_vendor/pkg_resources/__init__.py", line 3251, in <module>
    @_call_aside
  File "/home/arlan.uy/.local/lib/python3.7/site-packages/pip/_vendor/pkg_resources/__init__.py", line 3235, in _call_aside
    f(*args, **kwargs)
  File "/home/arlan.uy/.local/lib/python3.7/site-packages/pip/_vendor/pkg_resources/__init__.py", line 3279, in _initialize_master_working_set
    for dist in working_set
  File "/home/arlan.uy/.local/lib/python3.7/site-packages/pip/_vendor/pkg_resources/__init__.py", line 3279, in <genexpr>
    for dist in working_set
  File "/home/arlan.uy/.local/lib/python3.7/site-packages/pip/_vendor/pkg_resources/__init__.py", line 2783, in activate
    for pkg in self._get_metadata('namespace_packages.txt'):
  File "/home/arlan.uy/.local/lib/python3.7/site-packages/pip/_vendor/pkg_resources/__init__.py", line 2767, in _get_metadata
    for line in self.get_metadata_lines(name):
  File "/home/arlan.uy/.local/lib/python3.7/site-packages/pip/_vendor/pkg_resources/__init__.py", line 1432, in get_metadata_lines
    return yield_lines(self.get_metadata(name))
  File "/home/arlan.uy/.local/lib/python3.7/site-packages/pip/_vendor/pkg_resources/__init__.py", line 1420, in get_metadata
    value = self._get(path)
  File "/home/arlan.uy/.local/lib/python3.7/site-packages/pip/_vendor/pkg_resources/__init__.py", line 1616, in _get
    with open(path, 'rb') as stream:
OSError: [Errno 5] Input/output error: '/home/arlan.uy/.local/lib/python3.7/site-packages/matplotlib-3.0.0.dist-info/namespace_packages.txt'
srun: error: saliksik-cpu-21: task 1: Exited with exit code 1
Traceback (most recent call last):
  File "src/abstracts/gpu_selection.py", line 1, in <module>
    import pycuda.autoinit
  File "/home/arlan.uy/.local/lib/python3.7/site-packages/pycuda/autoinit.py", line 5, in <module>
    cuda.init()
pycuda._driver.Error: cuInit failed: unknown error
Traceback (most recent call last):
  File "src/abstracts/gpu_selection.py", line 1, in <module>
    import pycuda.autoinit
  File "/home/arlan.uy/.local/lib/python3.7/site-packages/pycuda/autoinit.py", line 5, in <module>
    cuda.init()
pycuda._driver.Error: cuInit failed: unknown error
Traceback (most recent call last):
  File "src/abstracts/gpu_selection.py", line 1, in <module>
    import pycuda.autoinit
  File "/home/arlan.uy/.local/lib/python3.7/site-packages/pycuda/autoinit.py", line 5, in <module>
    cuda.init()
pycuda._driver.Error: cuInit failed: unknown error
Traceback (most recent call last):
  File "src/abstracts/gpu_selection.py", line 1, in <module>
    import pycuda.autoinit
  File "/home/arlan.uy/.local/lib/python3.7/site-packages/pycuda/autoinit.py", line 5, in <module>
    cuda.init()
pycuda._driver.Error: cuInit failed: unknown error
Traceback (most recent call last):
  File "src/abstracts/gpu_selection.py", line 1, in <module>
    import pycuda.autoinit
  File "/home/arlan.uy/.local/lib/python3.7/site-packages/pycuda/autoinit.py", line 5, in <module>
    cuda.init()
pycuda._driver.Error: cuInit failed: unknown error
Traceback (most recent call last):
  File "src/abstracts/gpu_selection.py", line 1, in <module>
    import pycuda.autoinit
  File "/home/arlan.uy/.local/lib/python3.7/site-packages/pycuda/autoinit.py", line 5, in <module>
    cuda.init()
pycuda._driver.Error: cuInit failed: unknown error
Traceback (most recent call last):
  File "src/abstracts/gpu_selection.py", line 1, in <module>
    import pycuda.autoinit
  File "/home/arlan.uy/.local/lib/python3.7/site-packages/pycuda/autoinit.py", line 5, in <module>
    cuda.init()
pycuda._driver.Error: cuInit failed: unknown error
Traceback (most recent call last):
  File "src/abstracts/gpu_selection.py", line 1, in <module>
    import pycuda.autoinit
  File "/home/arlan.uy/.local/lib/python3.7/site-packages/pycuda/autoinit.py", line 5, in <module>
    cuda.init()
pycuda._driver.Error: cuInit failed: unknown error
srun: error: saliksik-cpu-21: tasks 0-7: Exited with exit code 1
